package mods.elysium.world.gen.feature;
import java.util.Random;

import mods.elysium.Elysium;
import net.minecraft.block.Block;
import net.minecraft.world.World;
import net.minecraft.world.gen.feature.WorldGenerator;

public class ElysiumGenHouse extends WorldGenerator
{
	protected int[] GetValidSpawnBlocks() {
		return new int[] {
		};
	}

	public boolean LocationIsValidSpawn(World world, int i, int j, int k){
		int distanceToAir = 0;
		int checkID = world.getBlockId(i, j, k);

		while (checkID != 0){
			distanceToAir++;
			checkID = world.getBlockId(i, j + distanceToAir, k);
		}

		if (distanceToAir > 3){
			return false;
		}
		j += distanceToAir - 1;

		int blockID = world.getBlockId(i, j, k);
		int blockIDAbove = world.getBlockId(i, j+1, k);
		int blockIDBelow = world.getBlockId(i, j-1, k);
		for (int x : GetValidSpawnBlocks()){
			if (blockIDAbove != 0){
				return false;
			}
			if (blockID == x){
				return true;
			}else if (blockID == Block.snow.blockID && blockIDBelow == x){
				return true;
			}
		}
		return false;
	}

	public ElysiumGenHouse() { }

	public boolean generate(World world, Random rand, int i, int j, int k) {
		//check that each corner is one of the valid spawn blocks
		if(!LocationIsValidSpawn(world, i, j, k) || !LocationIsValidSpawn(world, i + 21, j, k) || !LocationIsValidSpawn(world, i + 21, j, k + 11) || !LocationIsValidSpawn(world, i, j, k + 11))
		{
			return false;
		}

		world.setBlock(i + 0, j + 0, k + 0, Block.grass.blockID);
		world.setBlock(i + 0, j + 0, k + 1, Block.grass.blockID);
		world.setBlock(i + 0, j + 0, k + 2, Block.grass.blockID);
		world.setBlock(i + 0, j + 0, k + 3, Block.grass.blockID);
		world.setBlock(i + 0, j + 0, k + 4, Block.grass.blockID);
		world.setBlock(i + 0, j + 0, k + 5, Block.grass.blockID);
		world.setBlock(i + 0, j + 0, k + 6, Block.grass.blockID);
		world.setBlock(i + 0, j + 0, k + 7, Block.grass.blockID);
		world.setBlock(i + 0, j + 0, k + 8, Block.grass.blockID);
		world.setBlock(i + 0, j + 0, k + 9, Block.grass.blockID);
		world.setBlock(i + 0, j + 0, k + 10, Block.grass.blockID);
		world.setBlock(i + 0, j + 0, k + 11, Block.grass.blockID);
		world.setBlock(i + 0, j + 5, k + 0, Block.stairsStoneBrick.blockID, 2, 1);
		world.setBlock(i + 0, j + 5, k + 10, Block.stairsStoneBrick.blockID, 6, 1);
		world.setBlock(i + 0, j + 5, k + 11, Block.stairsStoneBrick.blockID, 3, 1);
		world.setBlock(i + 0, j + 6, k + 1, Block.stairsStoneBrick.blockID, 2, 1);
		world.setBlock(i + 0, j + 6, k + 2, Elysium.blockPalestoneBrick.blockID);
		world.setBlock(i + 0, j + 6, k + 9, Block.stairsStoneBrick.blockID, 6, 1);
		world.setBlock(i + 0, j + 6, k + 10, Block.stairsStoneBrick.blockID, 3, 1);
		world.setBlock(i + 0, j + 7, k + 2, Block.stairsStoneBrick.blockID, 2, 1);
		world.setBlock(i + 0, j + 7, k + 3, Elysium.blockPalestoneBrick.blockID);
		world.setBlock(i + 0, j + 7, k + 8, Block.stairsStoneBrick.blockID, 6, 1);
		world.setBlock(i + 0, j + 7, k + 9, Block.stairsStoneBrick.blockID, 3, 1);
		world.setBlock(i + 0, j + 8, k + 3, Block.stairsStoneBrick.blockID, 2, 1);
		world.setBlock(i + 0, j + 8, k + 4, Elysium.blockPalestoneBrick.blockID);
		world.setBlock(i + 0, j + 8, k + 7, Block.stairsStoneBrick.blockID, 6, 1);
		world.setBlock(i + 0, j + 8, k + 8, Block.stairsStoneBrick.blockID, 3, 1);
		world.setBlock(i + 0, j + 9, k + 4, Block.stairsStoneBrick.blockID, 2, 1);
		world.setBlock(i + 0, j + 9, k + 5, Block.stairsStoneBrick.blockID, 7, 1);
		world.setBlock(i + 0, j + 9, k + 6, Block.stairsStoneBrick.blockID, 6, 1);
		world.setBlock(i + 0, j + 9, k + 7, Block.stairsStoneBrick.blockID, 3, 1);
		world.setBlock(i + 0, j + 10, k + 5, Block.stairsStoneBrick.blockID, 2, 1);
		world.setBlock(i + 0, j + 10, k + 6, Block.stairsStoneBrick.blockID, 3, 1);
		world.setBlock(i + 1, j + 0, k + 0, Block.grass.blockID);
		world.setBlock(i + 1, j + 0, k + 1, Elysium.blockPalestoneBrick.blockID);
		world.setBlock(i + 1, j + 0, k + 2, Elysium.blockPalestoneBrick.blockID);
		world.setBlock(i + 1, j + 0, k + 3, Elysium.blockPalestoneBrick.blockID);
		world.setBlock(i + 1, j + 0, k + 4, Elysium.blockPalestoneBrick.blockID);
		world.setBlock(i + 1, j + 0, k + 5, Elysium.blockPalestoneBrick.blockID);
		world.setBlock(i + 1, j + 0, k + 6, Elysium.blockPalestoneBrick.blockID);
		world.setBlock(i + 1, j + 0, k + 7, Elysium.blockPalestoneBrick.blockID);
		world.setBlock(i + 1, j + 0, k + 8, Elysium.blockPalestoneBrick.blockID);
		world.setBlock(i + 1, j + 0, k + 9, Elysium.blockPalestoneBrick.blockID);
		world.setBlock(i + 1, j + 0, k + 10, Elysium.blockPalestoneBrick.blockID);
		world.setBlock(i + 1, j + 0, k + 11, Block.grass.blockID);
		world.setBlock(i + 1, j + 1, k + 1, Elysium.blockPalestoneBrickChiseld.blockID, 2, 1);
		world.setBlock(i + 1, j + 1, k + 2, Elysium.blockPalestoneBrick.blockID);
		world.setBlock(i + 1, j + 1, k + 3, Elysium.blockPalestoneBrick.blockID);
		world.setBlock(i + 1, j + 1, k + 4, Elysium.blockPalestoneBrick.blockID);
		world.setBlock(i + 1, j + 1, k + 5, Elysium.blockPalestoneBrick.blockID);
		world.setBlock(i + 1, j + 1, k + 6, Elysium.blockPalestoneBrick.blockID);
		world.setBlock(i + 1, j + 1, k + 7, Elysium.blockPalestoneBrick.blockID);
		world.setBlock(i + 1, j + 1, k + 8, Elysium.blockPalestoneBrick.blockID);
		world.setBlock(i + 1, j + 1, k + 9, Elysium.blockPalestoneBrick.blockID);
		world.setBlock(i + 1, j + 1, k + 10, Elysium.blockPalestoneBrickChiseld.blockID, 2, 1);
		world.setBlock(i + 1, j + 2, k + 1, Elysium.blockPalestoneBrickChiseld.blockID, 2, 1);
		world.setBlock(i + 1, j + 2, k + 2, Elysium.blockPalestoneBrick.blockID);
		world.setBlock(i + 1, j + 2, k + 3, Elysium.blockPalestoneBrick.blockID);
		world.setBlock(i + 1, j + 2, k + 4, Elysium.blockPalestoneBrick.blockID);
		world.setBlock(i + 1, j + 2, k + 5, Elysium.blockPalestoneBrick.blockID);
		world.setBlock(i + 1, j + 2, k + 6, Elysium.blockPalestoneBrick.blockID);
		world.setBlock(i + 1, j + 2, k + 7, Elysium.blockPalestoneBrick.blockID);
		world.setBlock(i + 1, j + 2, k + 8, Elysium.blockPalestoneBrick.blockID);
		world.setBlock(i + 1, j + 2, k + 9, Elysium.blockPalestoneBrick.blockID);
		world.setBlock(i + 1, j + 2, k + 10, Elysium.blockPalestoneBrickChiseld.blockID, 2, 1);
		world.setBlock(i + 1, j + 3, k + 1, Elysium.blockPalestoneBrickChiseld.blockID, 2, 1);
		world.setBlock(i + 1, j + 3, k + 2, Elysium.blockPalestoneBrick.blockID);
		world.setBlock(i + 1, j + 3, k + 3, Elysium.blockPalestoneBrick.blockID);
		world.setBlock(i + 1, j + 3, k + 4, Elysium.blockPalestoneBrick.blockID);
		world.setBlock(i + 1, j + 3, k + 5, Elysium.blockPalestoneBrick.blockID);
		world.setBlock(i + 1, j + 3, k + 6, Elysium.blockPalestoneBrick.blockID);
		world.setBlock(i + 1, j + 3, k + 7, Elysium.blockPalestoneBrick.blockID);
		world.setBlock(i + 1, j + 3, k + 8, Elysium.blockPalestoneBrick.blockID);
		world.setBlock(i + 1, j + 3, k + 9, Elysium.blockPalestoneBrick.blockID);
		world.setBlock(i + 1, j + 3, k + 10, Elysium.blockPalestoneBrickChiseld.blockID, 2, 1);
		world.setBlock(i + 1, j + 4, k + 1, Elysium.blockPalestoneBrickChiseld.blockID, 2, 1);
		world.setBlock(i + 1, j + 4, k + 2, Elysium.blockPalestoneBrick.blockID);
		world.setBlock(i + 1, j + 4, k + 3, Elysium.blockPalestoneBrick.blockID);
		world.setBlock(i + 1, j + 4, k + 4, Elysium.blockPalestoneBrick.blockID);
		world.setBlock(i + 1, j + 4, k + 5, Elysium.blockPalestoneBrick.blockID);
		world.setBlock(i + 1, j + 4, k + 6, Elysium.blockPalestoneBrick.blockID);
		world.setBlock(i + 1, j + 4, k + 7, Elysium.blockPalestoneBrick.blockID);
		world.setBlock(i + 1, j + 4, k + 8, Elysium.blockPalestoneBrick.blockID);
		world.setBlock(i + 1, j + 4, k + 9, Elysium.blockPalestoneBrick.blockID);
		world.setBlock(i + 1, j + 4, k + 10, Elysium.blockPalestoneBrickChiseld.blockID, 2, 1);
		world.setBlock(i + 1, j + 5, k + 0, Block.stairsStoneBrick.blockID, 2, 1);
		world.setBlock(i + 1, j + 5, k + 1, Elysium.blockPalestoneBrick.blockID);
		world.setBlock(i + 1, j + 5, k + 2, Elysium.blockPalestoneBrick.blockID);
		world.setBlock(i + 1, j + 5, k + 3, Elysium.blockPalestoneBrick.blockID);
		world.setBlock(i + 1, j + 5, k + 4, Elysium.blockPalestoneBrick.blockID);
		world.setBlock(i + 1, j + 5, k + 5, Elysium.blockPalestoneBrick.blockID);
		world.setBlock(i + 1, j + 5, k + 6, Elysium.blockPalestoneBrick.blockID);
		world.setBlock(i + 1, j + 5, k + 7, Elysium.blockPalestoneBrick.blockID);
		world.setBlock(i + 1, j + 5, k + 8, Elysium.blockPalestoneBrick.blockID);
		world.setBlock(i + 1, j + 5, k + 9, Elysium.blockPalestoneBrick.blockID);
		world.setBlock(i + 1, j + 5, k + 10, Elysium.blockPalestoneBrick.blockID);
		world.setBlock(i + 1, j + 5, k + 11, Block.stairsStoneBrick.blockID, 3, 1);
		world.setBlock(i + 1, j + 6, k + 1, Block.stairsStoneBrick.blockID, 2, 1);
		world.setBlock(i + 1, j + 6, k + 2, Elysium.blockPalestoneBrick.blockID);
		world.setBlock(i + 1, j + 6, k + 3, Elysium.blockPalestoneBrick.blockID);
		world.setBlock(i + 1, j + 6, k + 4, Elysium.blockPalestoneBrick.blockID);
		world.setBlock(i + 1, j + 6, k + 5, Elysium.blockPalestoneBrick.blockID);
		world.setBlock(i + 1, j + 6, k + 6, Elysium.blockPalestoneBrick.blockID);
		world.setBlock(i + 1, j + 6, k + 7, Elysium.blockPalestoneBrick.blockID);
		world.setBlock(i + 1, j + 6, k + 8, Elysium.blockPalestoneBrick.blockID);
		world.setBlock(i + 1, j + 6, k + 9, Elysium.blockPalestoneBrick.blockID);
		world.setBlock(i + 1, j + 6, k + 10, Block.stairsStoneBrick.blockID, 3, 1);
		world.setBlock(i + 1, j + 7, k + 2, Block.stairsStoneBrick.blockID, 2, 1);
		world.setBlock(i + 1, j + 7, k + 3, Elysium.blockPalestoneBrick.blockID);
		world.setBlock(i + 1, j + 7, k + 4, Elysium.blockPalestoneBrick.blockID);
		world.setBlock(i + 1, j + 7, k + 5, Elysium.blockPalestoneBrick.blockID);
		world.setBlock(i + 1, j + 7, k + 6, Elysium.blockPalestoneBrick.blockID);
		world.setBlock(i + 1, j + 7, k + 7, Elysium.blockPalestoneBrick.blockID);
		world.setBlock(i + 1, j + 7, k + 8, Elysium.blockPalestoneBrick.blockID);
		world.setBlock(i + 1, j + 7, k + 9, Block.stairsStoneBrick.blockID, 3, 1);
		world.setBlock(i + 1, j + 8, k + 3, Block.stairsStoneBrick.blockID, 2, 1);
		world.setBlock(i + 1, j + 8, k + 4, Elysium.blockPalestoneBrick.blockID);
		world.setBlock(i + 1, j + 8, k + 5, Elysium.blockPalestoneBrick.blockID);
		world.setBlock(i + 1, j + 8, k + 6, Elysium.blockPalestoneBrick.blockID);
		world.setBlock(i + 1, j + 8, k + 7, Elysium.blockPalestoneBrick.blockID);
		world.setBlock(i + 1, j + 8, k + 8, Block.stairsStoneBrick.blockID, 3, 1);
		world.setBlock(i + 1, j + 9, k + 4, Block.stairsStoneBrick.blockID, 2, 1);
		world.setBlock(i + 1, j + 9, k + 5, Elysium.blockPalestoneBrick.blockID);
		world.setBlock(i + 1, j + 9, k + 6, Elysium.blockPalestoneBrick.blockID);
		world.setBlock(i + 1, j + 9, k + 7, Block.stairsStoneBrick.blockID, 3, 1);
		world.setBlock(i + 1, j + 10, k + 5, Block.stairsStoneBrick.blockID, 2, 1);
		world.setBlock(i + 1, j + 10, k + 6, Block.stairsStoneBrick.blockID, 3, 1);
		world.setBlock(i + 2, j + 0, k + 0, Block.grass.blockID);
		world.setBlock(i + 2, j + 0, k + 1, Elysium.blockPalestoneBrick.blockID);
		world.setBlock(i + 2, j + 0, k + 2, Elysium.blockPalestonePillar.blockID, 1, 1);
		world.setBlock(i + 2, j + 0, k + 3, Elysium.blockPalestoneBrick.blockID);
		world.setBlock(i + 2, j + 0, k + 4, Elysium.blockPalestonePillar.blockID, 1, 1);
		world.setBlock(i + 2, j + 0, k + 5, Elysium.blockPalestoneBrick.blockID);
		world.setBlock(i + 2, j + 0, k + 6, Elysium.blockPalestonePillar.blockID, 1, 1);
		world.setBlock(i + 2, j + 0, k + 7, Elysium.blockPalestoneBrick.blockID);
		world.setBlock(i + 2, j + 0, k + 8, Elysium.blockPalestonePillar.blockID, 1, 1);
		world.setBlock(i + 2, j + 0, k + 9, Elysium.blockPalestoneBrick.blockID);
		world.setBlock(i + 2, j + 0, k + 10, Elysium.blockPalestoneBrick.blockID);
		world.setBlock(i + 2, j + 0, k + 11, Block.grass.blockID);
		world.setBlock(i + 2, j + 1, k + 1, Elysium.blockPalestoneBrick.blockID);
		world.setBlock(i + 2, j + 1, k + 10, Elysium.blockPalestoneBrick.blockID);
		world.setBlock(i + 2, j + 2, k + 1, Elysium.blockPalestoneBrick.blockID);
		world.setBlock(i + 2, j + 2, k + 10, Elysium.blockPalestoneBrick.blockID);
		world.setBlock(i + 2, j + 3, k + 1, Elysium.blockPalestoneBrick.blockID);
		world.setBlock(i + 2, j + 3, k + 10, Elysium.blockPalestoneBrick.blockID);
		world.setBlock(i + 2, j + 4, k + 1, Elysium.blockPalestoneBrick.blockID);
		world.setBlock(i + 2, j + 4, k + 10, Elysium.blockPalestoneBrick.blockID);
		world.setBlock(i + 2, j + 5, k + 0, Block.stairsStoneBrick.blockID, 2, 1);
		world.setBlock(i + 2, j + 5, k + 1, Elysium.blockPalestoneBrick.blockID);
		world.setBlock(i + 2, j + 5, k + 2, Elysium.blockPalestoneBrick.blockID);
		world.setBlock(i + 2, j + 5, k + 3, Elysium.blockPalestoneBrick.blockID);
		world.setBlock(i + 2, j + 5, k + 4, Elysium.blockPalestoneBrick.blockID);
		world.setBlock(i + 2, j + 5, k + 5, Elysium.blockPalestoneBrick.blockID);
		world.setBlock(i + 2, j + 5, k + 6, Elysium.blockPalestoneBrick.blockID);
		world.setBlock(i + 2, j + 5, k + 7, Elysium.blockPalestoneBrick.blockID);
		world.setBlock(i + 2, j + 5, k + 8, Elysium.blockPalestoneBrick.blockID);
		world.setBlock(i + 2, j + 5, k + 9, Elysium.blockPalestoneBrick.blockID);
		world.setBlock(i + 2, j + 5, k + 10, Elysium.blockPalestoneBrick.blockID);
		world.setBlock(i + 2, j + 5, k + 11, Block.stairsStoneBrick.blockID, 3, 1);
		world.setBlock(i + 2, j + 6, k + 1, Block.stairsStoneBrick.blockID, 2, 1);
		world.setBlock(i + 2, j + 6, k + 2, Elysium.blockPalestoneBrick.blockID);
		world.setBlock(i + 2, j + 6, k + 3, Elysium.blockPalestoneBrick.blockID);
		world.setBlock(i + 2, j + 6, k + 4, Elysium.blockPalestoneBrick.blockID);
		world.setBlock(i + 2, j + 6, k + 5, Elysium.blockPalestoneBrick.blockID);
		world.setBlock(i + 2, j + 6, k + 6, Elysium.blockPalestoneBrick.blockID);
		world.setBlock(i + 2, j + 6, k + 7, Elysium.blockPalestoneBrick.blockID);
		world.setBlock(i + 2, j + 6, k + 8, Elysium.blockPalestoneBrick.blockID);
		world.setBlock(i + 2, j + 6, k + 9, Elysium.blockPalestoneBrick.blockID);
		world.setBlock(i + 2, j + 6, k + 10, Block.stairsStoneBrick.blockID, 3, 1);
		world.setBlock(i + 2, j + 7, k + 2, Block.stairsStoneBrick.blockID, 2, 1);
		world.setBlock(i + 2, j + 7, k + 3, Elysium.blockPalestoneBrick.blockID);
		world.setBlock(i + 2, j + 7, k + 4, Elysium.blockPalestoneBrick.blockID);
		world.setBlock(i + 2, j + 7, k + 5, Elysium.blockPalestoneBrick.blockID);
		world.setBlock(i + 2, j + 7, k + 6, Elysium.blockPalestoneBrick.blockID);
		world.setBlock(i + 2, j + 7, k + 7, Elysium.blockPalestoneBrick.blockID);
		world.setBlock(i + 2, j + 7, k + 8, Elysium.blockPalestoneBrick.blockID);
		world.setBlock(i + 2, j + 7, k + 9, Block.stairsStoneBrick.blockID, 3, 1);
		world.setBlock(i + 2, j + 8, k + 3, Block.stairsStoneBrick.blockID, 2, 1);
		world.setBlock(i + 2, j + 8, k + 4, Elysium.blockPalestoneBrick.blockID);
		world.setBlock(i + 2, j + 8, k + 5, Elysium.blockPalestoneBrick.blockID);
		world.setBlock(i + 2, j + 8, k + 6, Elysium.blockPalestoneBrick.blockID);
		world.setBlock(i + 2, j + 8, k + 7, Elysium.blockPalestoneBrick.blockID);
		world.setBlock(i + 2, j + 8, k + 8, Block.stairsStoneBrick.blockID, 3, 1);
		world.setBlock(i + 2, j + 9, k + 4, Block.stairsStoneBrick.blockID, 2, 1);
		world.setBlock(i + 2, j + 9, k + 5, Elysium.blockPalestoneBrick.blockID);
		world.setBlock(i + 2, j + 9, k + 6, Elysium.blockPalestoneBrick.blockID);
		world.setBlock(i + 2, j + 9, k + 7, Block.stairsStoneBrick.blockID, 3, 1);
		world.setBlock(i + 2, j + 10, k + 5, Block.stairsStoneBrick.blockID, 2, 1);
		world.setBlock(i + 2, j + 10, k + 6, Block.stairsStoneBrick.blockID, 3, 1);
		world.setBlock(i + 3, j + 0, k + 0, Block.grass.blockID);
		world.setBlock(i + 3, j + 0, k + 1, Elysium.blockPalestoneBrick.blockID);
		world.setBlock(i + 3, j + 0, k + 2, Elysium.blockPalestoneBrick.blockID);
		world.setBlock(i + 3, j + 0, k + 3, Elysium.blockPalestonePillar.blockID);
		world.setBlock(i + 3, j + 0, k + 4, Elysium.blockPalestoneBrick.blockID);
		world.setBlock(i + 3, j + 0, k + 5, Elysium.blockPalestonePillar.blockID);
		world.setBlock(i + 3, j + 0, k + 6, Elysium.blockPalestoneBrick.blockID);
		world.setBlock(i + 3, j + 0, k + 7, Elysium.blockPalestonePillar.blockID);
		world.setBlock(i + 3, j + 0, k + 8, Elysium.blockPalestoneBrick.blockID);
		world.setBlock(i + 3, j + 0, k + 9, Elysium.blockPalestonePillar.blockID);
		world.setBlock(i + 3, j + 0, k + 10, Elysium.blockPalestoneBrick.blockID);
		world.setBlock(i + 3, j + 0, k + 11, Block.grass.blockID);
		world.setBlock(i + 3, j + 1, k + 1, Elysium.blockPalestoneBrick.blockID);
		world.setBlock(i + 3, j + 1, k + 10, Elysium.blockPalestoneBrick.blockID);
		world.setBlock(i + 3, j + 2, k + 1, Elysium.blockPalestoneBrick.blockID);
		world.setBlock(i + 3, j + 2, k + 10, Elysium.blockPalestoneBrick.blockID);
		world.setBlock(i + 3, j + 3, k + 1, Elysium.blockPalestoneBrick.blockID);
		world.setBlock(i + 3, j + 3, k + 10, Elysium.blockPalestoneBrick.blockID);
		world.setBlock(i + 3, j + 4, k + 1, Elysium.blockPalestoneBrick.blockID);
		world.setBlock(i + 3, j + 4, k + 10, Elysium.blockPalestoneBrick.blockID);
		world.setBlock(i + 3, j + 5, k + 0, Block.stairsStoneBrick.blockID, 2, 1);
		world.setBlock(i + 3, j + 5, k + 1, Elysium.blockPalestoneBrick.blockID);
		world.setBlock(i + 3, j + 5, k + 2, Elysium.blockPalestoneBrick.blockID);
		world.setBlock(i + 3, j + 5, k + 3, Elysium.blockPalestoneBrick.blockID);
		world.setBlock(i + 3, j + 5, k + 4, Elysium.blockPalestoneBrick.blockID);
		world.setBlock(i + 3, j + 5, k + 5, Elysium.blockPalestoneBrick.blockID);
		world.setBlock(i + 3, j + 5, k + 6, Elysium.blockPalestoneBrick.blockID);
		world.setBlock(i + 3, j + 5, k + 7, Elysium.blockPalestoneBrick.blockID);
		world.setBlock(i + 3, j + 5, k + 8, Elysium.blockPalestoneBrick.blockID);
		world.setBlock(i + 3, j + 5, k + 9, Elysium.blockPalestoneBrick.blockID);
		world.setBlock(i + 3, j + 5, k + 10, Elysium.blockPalestoneBrick.blockID);
		world.setBlock(i + 3, j + 5, k + 11, Block.stairsStoneBrick.blockID, 3, 1);
		world.setBlock(i + 3, j + 6, k + 1, Block.stairsStoneBrick.blockID, 2, 1);
		world.setBlock(i + 3, j + 6, k + 2, Elysium.blockPalestoneBrick.blockID);
		world.setBlock(i + 3, j + 6, k + 9, Elysium.blockPalestoneBrick.blockID);
		world.setBlock(i + 3, j + 6, k + 10, Block.stairsStoneBrick.blockID, 3, 1);
		world.setBlock(i + 3, j + 7, k + 2, Block.stairsStoneBrick.blockID, 2, 1);
		world.setBlock(i + 3, j + 7, k + 3, Elysium.blockPalestoneBrick.blockID);
		world.setBlock(i + 3, j + 7, k + 8, Elysium.blockPalestoneBrick.blockID);
		world.setBlock(i + 3, j + 7, k + 9, Block.stairsStoneBrick.blockID, 3, 1);
		world.setBlock(i + 3, j + 8, k + 3, Block.stairsStoneBrick.blockID, 2, 1);
		world.setBlock(i + 3, j + 8, k + 4, Elysium.blockPalestoneBrick.blockID);
		world.setBlock(i + 3, j + 8, k + 7, Elysium.blockPalestoneBrick.blockID);
		world.setBlock(i + 3, j + 8, k + 8, Block.stairsStoneBrick.blockID, 3, 1);
		world.setBlock(i + 3, j + 9, k + 4, Block.stairsStoneBrick.blockID, 2, 1);
		world.setBlock(i + 3, j + 9, k + 5, Elysium.blockPalestoneBrick.blockID);
		world.setBlock(i + 3, j + 9, k + 6, Elysium.blockPalestoneBrick.blockID);
		world.setBlock(i + 3, j + 9, k + 7, Block.stairsStoneBrick.blockID, 3, 1);
		world.setBlock(i + 3, j + 10, k + 5, Block.stairsStoneBrick.blockID, 2, 1);
		world.setBlock(i + 3, j + 10, k + 6, Block.stairsStoneBrick.blockID, 3, 1);
		world.setBlock(i + 4, j + 0, k + 0, Block.grass.blockID);
		world.setBlock(i + 4, j + 0, k + 1, Elysium.blockPalestoneBrick.blockID);
		world.setBlock(i + 4, j + 0, k + 2, Elysium.blockPalestonePillar.blockID);
		world.setBlock(i + 4, j + 0, k + 3, Elysium.blockPalestoneBrick.blockID);
		world.setBlock(i + 4, j + 0, k + 4, Elysium.blockPalestonePillar.blockID);
		world.setBlock(i + 4, j + 0, k + 5, Elysium.blockPalestoneBrick.blockID);
		world.setBlock(i + 4, j + 0, k + 6, Elysium.blockPalestonePillar.blockID);
		world.setBlock(i + 4, j + 0, k + 7, Elysium.blockPalestoneBrick.blockID);
		world.setBlock(i + 4, j + 0, k + 8, Elysium.blockPalestonePillar.blockID);
		world.setBlock(i + 4, j + 0, k + 9, Elysium.blockPalestoneBrick.blockID);
		world.setBlock(i + 4, j + 0, k + 10, Elysium.blockPalestoneBrick.blockID);
		world.setBlock(i + 4, j + 0, k + 11, Block.grass.blockID);
		world.setBlock(i + 4, j + 1, k + 1, Elysium.blockPalestoneBrick.blockID);
		world.setBlock(i + 4, j + 1, k + 10, Elysium.blockPalestoneBrick.blockID);
		world.setBlock(i + 4, j + 2, k + 1, Elysium.blockPalestoneBrick.blockID);
		world.setBlock(i + 4, j + 2, k + 10, Elysium.blockPalestoneBrick.blockID);
		world.setBlock(i + 4, j + 3, k + 1, Elysium.blockPalestoneBrick.blockID);
		world.setBlock(i + 4, j + 3, k + 10, Elysium.blockPalestoneBrick.blockID);
		world.setBlock(i + 4, j + 4, k + 1, Elysium.blockPalestoneBrick.blockID);
		world.setBlock(i + 4, j + 4, k + 10, Elysium.blockPalestoneBrick.blockID);
		world.setBlock(i + 4, j + 5, k + 0, Block.stairsStoneBrick.blockID, 2, 1);
		world.setBlock(i + 4, j + 5, k + 1, Elysium.blockPalestoneBrick.blockID);
		world.setBlock(i + 4, j + 5, k + 2, Elysium.blockPalestoneBrick.blockID);
		world.setBlock(i + 4, j + 5, k + 3, Elysium.blockPalestoneBrick.blockID);
		world.setBlock(i + 4, j + 5, k + 4, Elysium.blockPalestoneBrick.blockID);
		world.setBlock(i + 4, j + 5, k + 5, Elysium.blockPalestoneBrick.blockID);
		world.setBlock(i + 4, j + 5, k + 6, Elysium.blockPalestoneBrick.blockID);
		world.setBlock(i + 4, j + 5, k + 7, Elysium.blockPalestoneBrick.blockID);
		world.setBlock(i + 4, j + 5, k + 8, Elysium.blockPalestoneBrick.blockID);
		world.setBlock(i + 4, j + 5, k + 9, Elysium.blockPalestoneBrick.blockID);
		world.setBlock(i + 4, j + 5, k + 10, Elysium.blockPalestoneBrick.blockID);
		world.setBlock(i + 4, j + 5, k + 11, Block.stairsStoneBrick.blockID, 3, 1);
		world.setBlock(i + 4, j + 6, k + 1, Block.stairsStoneBrick.blockID, 2, 1);
		world.setBlock(i + 4, j + 6, k + 2, Elysium.blockPalestoneBrick.blockID);
		world.setBlock(i + 4, j + 6, k + 9, Elysium.blockPalestoneBrick.blockID);
		world.setBlock(i + 4, j + 6, k + 10, Block.stairsStoneBrick.blockID, 3, 1);
		world.setBlock(i + 4, j + 7, k + 2, Block.stairsStoneBrick.blockID, 2, 1);
		world.setBlock(i + 4, j + 7, k + 3, Elysium.blockPalestoneBrick.blockID);
		world.setBlock(i + 4, j + 7, k + 8, Elysium.blockPalestoneBrick.blockID);
		world.setBlock(i + 4, j + 7, k + 9, Block.stairsStoneBrick.blockID, 3, 1);
		world.setBlock(i + 4, j + 8, k + 3, Block.stairsStoneBrick.blockID, 2, 1);
		world.setBlock(i + 4, j + 8, k + 4, Elysium.blockPalestoneBrick.blockID);
		world.setBlock(i + 4, j + 8, k + 7, Elysium.blockPalestoneBrick.blockID);
		world.setBlock(i + 4, j + 8, k + 8, Block.stairsStoneBrick.blockID, 3, 1);
		world.setBlock(i + 4, j + 9, k + 4, Block.stairsStoneBrick.blockID, 2, 1);
		world.setBlock(i + 4, j + 9, k + 5, Elysium.blockPalestoneBrick.blockID);
		world.setBlock(i + 4, j + 9, k + 6, Elysium.blockPalestoneBrick.blockID);
		world.setBlock(i + 4, j + 9, k + 7, Block.stairsStoneBrick.blockID, 3, 1);
		world.setBlock(i + 4, j + 10, k + 5, Block.stairsStoneBrick.blockID, 2, 1);
		world.setBlock(i + 4, j + 10, k + 6, Block.stairsStoneBrick.blockID, 3, 1);
		world.setBlock(i + 5, j + 0, k + 0, Block.grass.blockID);
		world.setBlock(i + 5, j + 0, k + 1, Elysium.blockPalestoneBrick.blockID);
		world.setBlock(i + 5, j + 0, k + 2, Elysium.blockPalestoneBrick.blockID);
		world.setBlock(i + 5, j + 0, k + 3, Elysium.blockPalestonePillar.blockID);
		world.setBlock(i + 5, j + 0, k + 4, Elysium.blockPalestoneBrick.blockID);
		world.setBlock(i + 5, j + 0, k + 5, Elysium.blockPalestonePillar.blockID);
		world.setBlock(i + 5, j + 0, k + 6, Elysium.blockPalestoneBrick.blockID);
		world.setBlock(i + 5, j + 0, k + 7, Elysium.blockPalestonePillar.blockID);
		world.setBlock(i + 5, j + 0, k + 8, Elysium.blockPalestoneBrick.blockID);
		world.setBlock(i + 5, j + 0, k + 9, Elysium.blockPalestonePillar.blockID);
		world.setBlock(i + 5, j + 0, k + 10, Elysium.blockPalestoneBrick.blockID);
		world.setBlock(i + 5, j + 0, k + 11, Block.grass.blockID);
		world.setBlock(i + 5, j + 1, k + 1, Elysium.blockPalestoneBrick.blockID);
		world.setBlock(i + 5, j + 1, k + 10, Elysium.blockPalestoneBrick.blockID);
		world.setBlock(i + 5, j + 2, k + 1, Elysium.blockPalestoneBrick.blockID);
		world.setBlock(i + 5, j + 2, k + 10, Elysium.blockPalestoneBrick.blockID);
		world.setBlock(i + 5, j + 3, k + 1, Elysium.blockPalestoneBrick.blockID);
		world.setBlock(i + 5, j + 3, k + 10, Elysium.blockPalestoneBrick.blockID);
		world.setBlock(i + 5, j + 4, k + 1, Elysium.blockPalestoneBrick.blockID);
		world.setBlock(i + 5, j + 4, k + 10, Elysium.blockPalestoneBrick.blockID);
		world.setBlock(i + 5, j + 5, k + 0, Block.stairsStoneBrick.blockID, 2, 1);
		world.setBlock(i + 5, j + 5, k + 1, Elysium.blockPalestoneBrick.blockID);
		world.setBlock(i + 5, j + 5, k + 2, Elysium.blockPalestoneBrick.blockID);
		world.setBlock(i + 5, j + 5, k + 3, Elysium.blockPalestoneBrick.blockID);
		world.setBlock(i + 5, j + 5, k + 4, Elysium.blockPalestoneBrick.blockID);
		world.setBlock(i + 5, j + 5, k + 5, Elysium.blockPalestoneBrick.blockID);
		world.setBlock(i + 5, j + 5, k + 6, Elysium.blockPalestoneBrick.blockID);
		world.setBlock(i + 5, j + 5, k + 7, Elysium.blockPalestoneBrick.blockID);
		world.setBlock(i + 5, j + 5, k + 8, Elysium.blockPalestoneBrick.blockID);
		world.setBlock(i + 5, j + 5, k + 9, Elysium.blockPalestoneBrick.blockID);
		world.setBlock(i + 5, j + 5, k + 10, Elysium.blockPalestoneBrick.blockID);
		world.setBlock(i + 5, j + 5, k + 11, Block.stairsStoneBrick.blockID, 3, 1);
		world.setBlock(i + 5, j + 6, k + 1, Block.stairsStoneBrick.blockID, 2, 1);
		world.setBlock(i + 5, j + 6, k + 2, Elysium.blockPalestoneBrick.blockID);
		world.setBlock(i + 5, j + 6, k + 9, Elysium.blockPalestoneBrick.blockID);
		world.setBlock(i + 5, j + 6, k + 10, Block.stairsStoneBrick.blockID, 3, 1);
		world.setBlock(i + 5, j + 7, k + 2, Block.stairsStoneBrick.blockID, 2, 1);
		world.setBlock(i + 5, j + 7, k + 3, Elysium.blockPalestoneBrick.blockID);
		world.setBlock(i + 5, j + 7, k + 8, Elysium.blockPalestoneBrick.blockID);
		world.setBlock(i + 5, j + 7, k + 9, Block.stairsStoneBrick.blockID, 3, 1);
		world.setBlock(i + 5, j + 8, k + 3, Block.stairsStoneBrick.blockID, 2, 1);
		world.setBlock(i + 5, j + 8, k + 4, Elysium.blockPalestoneBrick.blockID);
		world.setBlock(i + 5, j + 8, k + 7, Elysium.blockPalestoneBrick.blockID);
		world.setBlock(i + 5, j + 8, k + 8, Block.stairsStoneBrick.blockID, 3, 1);
		world.setBlock(i + 5, j + 9, k + 4, Block.stairsStoneBrick.blockID, 2, 1);
		world.setBlock(i + 5, j + 9, k + 5, Elysium.blockPalestoneBrick.blockID);
		world.setBlock(i + 5, j + 9, k + 6, Elysium.blockPalestoneBrick.blockID);
		world.setBlock(i + 5, j + 9, k + 7, Block.stairsStoneBrick.blockID, 3, 1);
		world.setBlock(i + 5, j + 10, k + 5, Block.stairsStoneBrick.blockID, 2, 1);
		world.setBlock(i + 5, j + 10, k + 6, Block.stairsStoneBrick.blockID, 3, 1);
		world.setBlock(i + 6, j + 0, k + 0, Block.grass.blockID);
		world.setBlock(i + 6, j + 0, k + 1, Elysium.blockPalestoneBrick.blockID);
		world.setBlock(i + 6, j + 0, k + 2, Elysium.blockPalestonePillar.blockID);
		world.setBlock(i + 6, j + 0, k + 3, Elysium.blockPalestoneBrick.blockID);
		world.setBlock(i + 6, j + 0, k + 4, Elysium.blockPalestonePillar.blockID);
		world.setBlock(i + 6, j + 0, k + 5, Elysium.blockPalestoneBrick.blockID);
		world.setBlock(i + 6, j + 0, k + 6, Elysium.blockPalestonePillar.blockID);
		world.setBlock(i + 6, j + 0, k + 7, Elysium.blockPalestoneBrick.blockID);
		world.setBlock(i + 6, j + 0, k + 8, Elysium.blockPalestonePillar.blockID);
		world.setBlock(i + 6, j + 0, k + 9, Elysium.blockPalestoneBrick.blockID);
		world.setBlock(i + 6, j + 0, k + 10, Elysium.blockPalestoneBrick.blockID);
		world.setBlock(i + 6, j + 0, k + 11, Block.grass.blockID);
		world.setBlock(i + 6, j + 1, k + 1, Elysium.blockPalestoneBrick.blockID);
		world.setBlock(i + 6, j + 1, k + 10, Elysium.blockPalestoneBrick.blockID);
		world.setBlock(i + 6, j + 2, k + 1, Elysium.blockPalestoneBrick.blockID);
		world.setBlock(i + 6, j + 2, k + 10, Elysium.blockPalestoneBrick.blockID);
		world.setBlock(i + 6, j + 3, k + 1, Elysium.blockPalestoneBrick.blockID);
		world.setBlock(i + 6, j + 3, k + 10, Elysium.blockPalestoneBrick.blockID);
		world.setBlock(i + 6, j + 4, k + 1, Elysium.blockPalestoneBrick.blockID);
		world.setBlock(i + 6, j + 4, k + 10, Elysium.blockPalestoneBrick.blockID);
		world.setBlock(i + 6, j + 5, k + 0, Block.stairsStoneBrick.blockID, 2, 1);
		world.setBlock(i + 6, j + 5, k + 1, Elysium.blockPalestoneBrick.blockID);
		world.setBlock(i + 6, j + 5, k + 2, Elysium.blockPalestoneBrick.blockID);
		world.setBlock(i + 6, j + 5, k + 3, Elysium.blockPalestoneBrick.blockID);
		world.setBlock(i + 6, j + 5, k + 4, Elysium.blockPalestoneBrick.blockID);
		world.setBlock(i + 6, j + 5, k + 5, Elysium.blockPalestoneBrick.blockID);
		world.setBlock(i + 6, j + 5, k + 6, Elysium.blockPalestoneBrick.blockID);
		world.setBlock(i + 6, j + 5, k + 7, Elysium.blockPalestoneBrick.blockID);
		world.setBlock(i + 6, j + 5, k + 8, Elysium.blockPalestoneBrick.blockID);
		world.setBlock(i + 6, j + 5, k + 9, Elysium.blockPalestoneBrick.blockID);
		world.setBlock(i + 6, j + 5, k + 10, Elysium.blockPalestoneBrick.blockID);
		world.setBlock(i + 6, j + 5, k + 11, Block.stairsStoneBrick.blockID, 3, 1);
		world.setBlock(i + 6, j + 6, k + 1, Block.stairsStoneBrick.blockID, 2, 1);
		world.setBlock(i + 6, j + 6, k + 2, Elysium.blockPalestoneBrick.blockID);
		world.setBlock(i + 6, j + 6, k + 9, Elysium.blockPalestoneBrick.blockID);
		world.setBlock(i + 6, j + 6, k + 10, Block.stairsStoneBrick.blockID, 3, 1);
		world.setBlock(i + 6, j + 7, k + 2, Block.stairsStoneBrick.blockID, 2, 1);
		world.setBlock(i + 6, j + 7, k + 3, Elysium.blockPalestoneBrick.blockID);
		world.setBlock(i + 6, j + 7, k + 8, Elysium.blockPalestoneBrick.blockID);
		world.setBlock(i + 6, j + 7, k + 9, Block.stairsStoneBrick.blockID, 3, 1);
		world.setBlock(i + 6, j + 8, k + 3, Block.stairsStoneBrick.blockID, 2, 1);
		world.setBlock(i + 6, j + 8, k + 4, Elysium.blockPalestoneBrick.blockID);
		world.setBlock(i + 6, j + 8, k + 7, Elysium.blockPalestoneBrick.blockID);
		world.setBlock(i + 6, j + 8, k + 8, Block.stairsStoneBrick.blockID, 3, 1);
		world.setBlock(i + 6, j + 9, k + 4, Block.stairsStoneBrick.blockID, 2, 1);
		world.setBlock(i + 6, j + 9, k + 5, Elysium.blockPalestoneBrick.blockID);
		world.setBlock(i + 6, j + 9, k + 6, Elysium.blockPalestoneBrick.blockID);
		world.setBlock(i + 6, j + 9, k + 7, Block.stairsStoneBrick.blockID, 3, 1);
		world.setBlock(i + 6, j + 10, k + 5, Block.stairsStoneBrick.blockID, 2, 1);
		world.setBlock(i + 6, j + 10, k + 6, Block.stairsStoneBrick.blockID, 3, 1);
		world.setBlock(i + 7, j + 0, k + 0, Block.grass.blockID);
		world.setBlock(i + 7, j + 0, k + 1, Elysium.blockPalestoneBrick.blockID);
		world.setBlock(i + 7, j + 0, k + 2, Elysium.blockPalestoneBrick.blockID);
		world.setBlock(i + 7, j + 0, k + 3, Elysium.blockPalestonePillar.blockID);
		world.setBlock(i + 7, j + 0, k + 4, Elysium.blockPalestoneBrick.blockID);
		world.setBlock(i + 7, j + 0, k + 5, Elysium.blockPalestonePillar.blockID);
		world.setBlock(i + 7, j + 0, k + 6, Elysium.blockPalestoneBrick.blockID);
		world.setBlock(i + 7, j + 0, k + 7, Elysium.blockPalestonePillar.blockID);
		world.setBlock(i + 7, j + 0, k + 8, Elysium.blockPalestoneBrick.blockID);
		world.setBlock(i + 7, j + 0, k + 9, Elysium.blockPalestonePillar.blockID);
		world.setBlock(i + 7, j + 0, k + 10, Elysium.blockPalestoneBrick.blockID);
		world.setBlock(i + 7, j + 0, k + 11, Block.grass.blockID);
		world.setBlock(i + 7, j + 1, k + 1, Elysium.blockPalestoneBrick.blockID);
		world.setBlock(i + 7, j + 1, k + 10, Elysium.blockPalestoneBrick.blockID);
		world.setBlock(i + 7, j + 2, k + 1, Elysium.blockPalestoneBrick.blockID);
		world.setBlock(i + 7, j + 2, k + 10, Elysium.blockPalestoneBrick.blockID);
		world.setBlock(i + 7, j + 3, k + 1, Elysium.blockPalestoneBrick.blockID);
		world.setBlock(i + 7, j + 3, k + 10, Elysium.blockPalestoneBrick.blockID);
		world.setBlock(i + 7, j + 4, k + 1, Elysium.blockPalestoneBrick.blockID);
		world.setBlock(i + 7, j + 4, k + 10, Elysium.blockPalestoneBrick.blockID);
		world.setBlock(i + 7, j + 5, k + 0, Block.stairsStoneBrick.blockID, 2, 1);
		world.setBlock(i + 7, j + 5, k + 1, Elysium.blockPalestoneBrick.blockID);
		world.setBlock(i + 7, j + 5, k + 2, Elysium.blockPalestoneBrick.blockID);
		world.setBlock(i + 7, j + 5, k + 3, Elysium.blockPalestoneBrick.blockID);
		world.setBlock(i + 7, j + 5, k + 4, Elysium.blockPalestoneBrick.blockID);
		world.setBlock(i + 7, j + 5, k + 5, Elysium.blockPalestoneBrick.blockID);
		world.setBlock(i + 7, j + 5, k + 6, Elysium.blockPalestoneBrick.blockID);
		world.setBlock(i + 7, j + 5, k + 7, Elysium.blockPalestoneBrick.blockID);
		world.setBlock(i + 7, j + 5, k + 8, Elysium.blockPalestoneBrick.blockID);
		world.setBlock(i + 7, j + 5, k + 9, Elysium.blockPalestoneBrick.blockID);
		world.setBlock(i + 7, j + 5, k + 10, Elysium.blockPalestoneBrick.blockID);
		world.setBlock(i + 7, j + 5, k + 11, Block.stairsStoneBrick.blockID, 3, 1);
		world.setBlock(i + 7, j + 6, k + 1, Block.stairsStoneBrick.blockID, 2, 1);
		world.setBlock(i + 7, j + 6, k + 2, Elysium.blockPalestoneBrick.blockID);
		world.setBlock(i + 7, j + 6, k + 9, Elysium.blockPalestoneBrick.blockID);
		world.setBlock(i + 7, j + 6, k + 10, Block.stairsStoneBrick.blockID, 3, 1);
		world.setBlock(i + 7, j + 7, k + 2, Block.stairsStoneBrick.blockID, 2, 1);
		world.setBlock(i + 7, j + 7, k + 3, Elysium.blockPalestoneBrick.blockID);
		world.setBlock(i + 7, j + 7, k + 8, Elysium.blockPalestoneBrick.blockID);
		world.setBlock(i + 7, j + 7, k + 9, Block.stairsStoneBrick.blockID, 3, 1);
		world.setBlock(i + 7, j + 8, k + 3, Block.stairsStoneBrick.blockID, 2, 1);
		world.setBlock(i + 7, j + 8, k + 4, Elysium.blockPalestoneBrick.blockID);
		world.setBlock(i + 7, j + 8, k + 7, Elysium.blockPalestoneBrick.blockID);
		world.setBlock(i + 7, j + 8, k + 8, Block.stairsStoneBrick.blockID, 3, 1);
		world.setBlock(i + 7, j + 9, k + 4, Block.stairsStoneBrick.blockID, 2, 1);
		world.setBlock(i + 7, j + 9, k + 5, Elysium.blockPalestoneBrick.blockID);
		world.setBlock(i + 7, j + 9, k + 6, Elysium.blockPalestoneBrick.blockID);
		world.setBlock(i + 7, j + 9, k + 7, Block.stairsStoneBrick.blockID, 3, 1);
		world.setBlock(i + 7, j + 10, k + 5, Block.stairsStoneBrick.blockID, 2, 1);
		world.setBlock(i + 7, j + 10, k + 6, Block.stairsStoneBrick.blockID, 3, 1);
		world.setBlock(i + 8, j + 0, k + 0, Block.grass.blockID);
		world.setBlock(i + 8, j + 0, k + 1, Elysium.blockPalestoneBrick.blockID);
		world.setBlock(i + 8, j + 0, k + 2, Elysium.blockPalestonePillar.blockID);
		world.setBlock(i + 8, j + 0, k + 3, Elysium.blockPalestoneBrick.blockID);
		world.setBlock(i + 8, j + 0, k + 4, Elysium.blockPalestonePillar.blockID);
		world.setBlock(i + 8, j + 0, k + 5, Elysium.blockPalestoneBrick.blockID);
		world.setBlock(i + 8, j + 0, k + 6, Elysium.blockPalestonePillar.blockID);
		world.setBlock(i + 8, j + 0, k + 7, Elysium.blockPalestoneBrick.blockID);
		world.setBlock(i + 8, j + 0, k + 8, Elysium.blockPalestonePillar.blockID);
		world.setBlock(i + 8, j + 0, k + 9, Elysium.blockPalestoneBrick.blockID);
		world.setBlock(i + 8, j + 0, k + 10, Elysium.blockPalestoneBrick.blockID);
		world.setBlock(i + 8, j + 0, k + 11, Block.grass.blockID);
		world.setBlock(i + 8, j + 1, k + 1, Elysium.blockPalestoneBrick.blockID);
		world.setBlock(i + 8, j + 1, k + 10, Elysium.blockPalestoneBrick.blockID);
		world.setBlock(i + 8, j + 2, k + 1, Elysium.blockPalestoneBrick.blockID);
		world.setBlock(i + 8, j + 2, k + 10, Elysium.blockPalestoneBrick.blockID);
		world.setBlock(i + 8, j + 3, k + 1, Elysium.blockPalestoneBrick.blockID);
		world.setBlock(i + 8, j + 3, k + 10, Elysium.blockPalestoneBrick.blockID);
		world.setBlock(i + 8, j + 4, k + 1, Elysium.blockPalestoneBrick.blockID);
		world.setBlock(i + 8, j + 4, k + 10, Elysium.blockPalestoneBrick.blockID);
		world.setBlock(i + 8, j + 5, k + 0, Block.stairsStoneBrick.blockID, 2, 1);
		world.setBlock(i + 8, j + 5, k + 1, Elysium.blockPalestoneBrick.blockID);
		world.setBlock(i + 8, j + 5, k + 2, Elysium.blockPalestoneBrick.blockID);
		world.setBlock(i + 8, j + 5, k + 3, Elysium.blockPalestoneBrick.blockID);
		world.setBlock(i + 8, j + 5, k + 4, Elysium.blockPalestoneBrick.blockID);
		world.setBlock(i + 8, j + 5, k + 5, Elysium.blockPalestoneBrick.blockID);
		world.setBlock(i + 8, j + 5, k + 6, Elysium.blockPalestoneBrick.blockID);
		world.setBlock(i + 8, j + 5, k + 7, Elysium.blockPalestoneBrick.blockID);
		world.setBlock(i + 8, j + 5, k + 8, Elysium.blockPalestoneBrick.blockID);
		world.setBlock(i + 8, j + 5, k + 9, Elysium.blockPalestoneBrick.blockID);
		world.setBlock(i + 8, j + 5, k + 10, Elysium.blockPalestoneBrick.blockID);
		world.setBlock(i + 8, j + 5, k + 11, Block.stairsStoneBrick.blockID, 3, 1);
		world.setBlock(i + 8, j + 6, k + 1, Block.stairsStoneBrick.blockID, 2, 1);
		world.setBlock(i + 8, j + 6, k + 2, Elysium.blockPalestoneBrick.blockID);
		world.setBlock(i + 8, j + 6, k + 9, Elysium.blockPalestoneBrick.blockID);
		world.setBlock(i + 8, j + 6, k + 10, Block.stairsStoneBrick.blockID, 3, 1);
		world.setBlock(i + 8, j + 7, k + 2, Block.stairsStoneBrick.blockID, 2, 1);
		world.setBlock(i + 8, j + 7, k + 3, Elysium.blockPalestoneBrick.blockID);
		world.setBlock(i + 8, j + 7, k + 8, Elysium.blockPalestoneBrick.blockID);
		world.setBlock(i + 8, j + 7, k + 9, Block.stairsStoneBrick.blockID, 3, 1);
		world.setBlock(i + 8, j + 8, k + 3, Block.stairsStoneBrick.blockID, 2, 1);
		world.setBlock(i + 8, j + 8, k + 4, Elysium.blockPalestoneBrick.blockID);
		world.setBlock(i + 8, j + 8, k + 7, Elysium.blockPalestoneBrick.blockID);
		world.setBlock(i + 8, j + 8, k + 8, Block.stairsStoneBrick.blockID, 3, 1);
		world.setBlock(i + 8, j + 9, k + 4, Block.stairsStoneBrick.blockID, 2, 1);
		world.setBlock(i + 8, j + 9, k + 5, Elysium.blockPalestoneBrick.blockID);
		world.setBlock(i + 8, j + 9, k + 6, Elysium.blockPalestoneBrick.blockID);
		world.setBlock(i + 8, j + 9, k + 7, Block.stairsStoneBrick.blockID, 3, 1);
		world.setBlock(i + 8, j + 10, k + 5, Block.stairsStoneBrick.blockID, 2, 1);
		world.setBlock(i + 8, j + 10, k + 6, Block.stairsStoneBrick.blockID, 3, 1);
		world.setBlock(i + 9, j + 0, k + 0, Block.grass.blockID);
		world.setBlock(i + 9, j + 0, k + 1, Elysium.blockPalestoneBrick.blockID);
		world.setBlock(i + 9, j + 0, k + 2, Elysium.blockPalestoneBrick.blockID);
		world.setBlock(i + 9, j + 0, k + 3, Elysium.blockPalestonePillar.blockID);
		world.setBlock(i + 9, j + 0, k + 4, Elysium.blockPalestoneBrick.blockID);
		world.setBlock(i + 9, j + 0, k + 5, Elysium.blockPalestonePillar.blockID);
		world.setBlock(i + 9, j + 0, k + 6, Elysium.blockPalestoneBrick.blockID);
		world.setBlock(i + 9, j + 0, k + 7, Elysium.blockPalestonePillar.blockID);
		world.setBlock(i + 9, j + 0, k + 8, Elysium.blockPalestoneBrick.blockID);
		world.setBlock(i + 9, j + 0, k + 9, Elysium.blockPalestonePillar.blockID);
		world.setBlock(i + 9, j + 0, k + 10, Elysium.blockPalestoneBrick.blockID);
		world.setBlock(i + 9, j + 0, k + 11, Block.grass.blockID);
		world.setBlock(i + 9, j + 1, k + 1, Elysium.blockPalestoneBrick.blockID);
		world.setBlock(i + 9, j + 1, k + 10, Elysium.blockPalestoneBrick.blockID);
		world.setBlock(i + 9, j + 2, k + 1, Elysium.blockPalestoneBrick.blockID);
		world.setBlock(i + 9, j + 2, k + 10, Elysium.blockPalestoneBrick.blockID);
		world.setBlock(i + 9, j + 3, k + 1, Elysium.blockPalestoneBrick.blockID);
		world.setBlock(i + 9, j + 3, k + 10, Elysium.blockPalestoneBrick.blockID);
		world.setBlock(i + 9, j + 4, k + 1, Elysium.blockPalestoneBrick.blockID);
		world.setBlock(i + 9, j + 4, k + 10, Elysium.blockPalestoneBrick.blockID);
		world.setBlock(i + 9, j + 5, k + 0, Block.stairsStoneBrick.blockID, 2, 1);
		world.setBlock(i + 9, j + 5, k + 1, Elysium.blockPalestoneBrick.blockID);
		world.setBlock(i + 9, j + 5, k + 2, Elysium.blockPalestoneBrick.blockID);
		world.setBlock(i + 9, j + 5, k + 3, Elysium.blockPalestoneBrick.blockID);
		world.setBlock(i + 9, j + 5, k + 4, Elysium.blockPalestoneBrick.blockID);
		world.setBlock(i + 9, j + 5, k + 5, Elysium.blockPalestoneBrick.blockID);
		world.setBlock(i + 9, j + 5, k + 6, Elysium.blockPalestoneBrick.blockID);
		world.setBlock(i + 9, j + 5, k + 7, Elysium.blockPalestoneBrick.blockID);
		world.setBlock(i + 9, j + 5, k + 8, Elysium.blockPalestoneBrick.blockID);
		world.setBlock(i + 9, j + 5, k + 9, Elysium.blockPalestoneBrick.blockID);
		world.setBlock(i + 9, j + 5, k + 10, Elysium.blockPalestoneBrick.blockID);
		world.setBlock(i + 9, j + 5, k + 11, Block.stairsStoneBrick.blockID, 3, 1);
		world.setBlock(i + 9, j + 6, k + 1, Block.stairsStoneBrick.blockID, 2, 1);
		world.setBlock(i + 9, j + 6, k + 2, Elysium.blockPalestoneBrick.blockID);
		world.setBlock(i + 9, j + 6, k + 9, Elysium.blockPalestoneBrick.blockID);
		world.setBlock(i + 9, j + 6, k + 10, Block.stairsStoneBrick.blockID, 3, 1);
		world.setBlock(i + 9, j + 7, k + 2, Block.stairsStoneBrick.blockID, 2, 1);
		world.setBlock(i + 9, j + 7, k + 3, Elysium.blockPalestoneBrick.blockID);
		world.setBlock(i + 9, j + 7, k + 8, Elysium.blockPalestoneBrick.blockID);
		world.setBlock(i + 9, j + 7, k + 9, Block.stairsStoneBrick.blockID, 3, 1);
		world.setBlock(i + 9, j + 8, k + 3, Block.stairsStoneBrick.blockID, 2, 1);
		world.setBlock(i + 9, j + 8, k + 4, Elysium.blockPalestoneBrick.blockID);
		world.setBlock(i + 9, j + 8, k + 7, Elysium.blockPalestoneBrick.blockID);
		world.setBlock(i + 9, j + 8, k + 8, Block.stairsStoneBrick.blockID, 3, 1);
		world.setBlock(i + 9, j + 9, k + 4, Block.stairsStoneBrick.blockID, 2, 1);
		world.setBlock(i + 9, j + 9, k + 5, Elysium.blockPalestoneBrick.blockID);
		world.setBlock(i + 9, j + 9, k + 6, Elysium.blockPalestoneBrick.blockID);
		world.setBlock(i + 9, j + 9, k + 7, Block.stairsStoneBrick.blockID, 3, 1);
		world.setBlock(i + 9, j + 10, k + 5, Block.stairsStoneBrick.blockID, 2, 1);
		world.setBlock(i + 9, j + 10, k + 6, Block.stairsStoneBrick.blockID, 3, 1);
		world.setBlock(i + 10, j + 0, k + 0, Block.grass.blockID);
		world.setBlock(i + 10, j + 0, k + 1, Elysium.blockPalestoneBrick.blockID);
		world.setBlock(i + 10, j + 0, k + 2, Elysium.blockPalestonePillar.blockID);
		world.setBlock(i + 10, j + 0, k + 3, Elysium.blockPalestoneBrick.blockID);
		world.setBlock(i + 10, j + 0, k + 4, Elysium.blockPalestonePillar.blockID);
		world.setBlock(i + 10, j + 0, k + 5, Elysium.blockPalestoneBrick.blockID);
		world.setBlock(i + 10, j + 0, k + 6, Elysium.blockPalestonePillar.blockID);
		world.setBlock(i + 10, j + 0, k + 7, Elysium.blockPalestoneBrick.blockID);
		world.setBlock(i + 10, j + 0, k + 8, Elysium.blockPalestonePillar.blockID);
		world.setBlock(i + 10, j + 0, k + 9, Elysium.blockPalestoneBrick.blockID);
		world.setBlock(i + 10, j + 0, k + 10, Elysium.blockPalestoneBrick.blockID);
		world.setBlock(i + 10, j + 0, k + 11, Block.grass.blockID);
		world.setBlock(i + 10, j + 1, k + 1, Elysium.blockPalestoneBrick.blockID);
		world.setBlock(i + 10, j + 1, k + 10, Elysium.blockPalestoneBrick.blockID);
		world.setBlock(i + 10, j + 2, k + 1, Elysium.blockPalestoneBrick.blockID);
		world.setBlock(i + 10, j + 2, k + 10, Elysium.blockPalestoneBrick.blockID);
		world.setBlock(i + 10, j + 3, k + 1, Elysium.blockPalestoneBrick.blockID);
		world.setBlock(i + 10, j + 3, k + 10, Elysium.blockPalestoneBrick.blockID);
		world.setBlock(i + 10, j + 4, k + 1, Elysium.blockPalestoneBrick.blockID);
		world.setBlock(i + 10, j + 4, k + 10, Elysium.blockPalestoneBrick.blockID);
		world.setBlock(i + 10, j + 5, k + 0, Block.stairsStoneBrick.blockID, 2, 1);
		world.setBlock(i + 10, j + 5, k + 1, Elysium.blockPalestoneBrick.blockID);
		world.setBlock(i + 10, j + 5, k + 2, Elysium.blockPalestoneBrick.blockID);
		world.setBlock(i + 10, j + 5, k + 3, Elysium.blockPalestoneBrick.blockID);
		world.setBlock(i + 10, j + 5, k + 4, Elysium.blockPalestoneBrick.blockID);
		world.setBlock(i + 10, j + 5, k + 5, Elysium.blockPalestoneBrick.blockID);
		world.setBlock(i + 10, j + 5, k + 6, Elysium.blockPalestoneBrick.blockID);
		world.setBlock(i + 10, j + 5, k + 7, Elysium.blockPalestoneBrick.blockID);
		world.setBlock(i + 10, j + 5, k + 8, Elysium.blockPalestoneBrick.blockID);
		world.setBlock(i + 10, j + 5, k + 9, Elysium.blockPalestoneBrick.blockID);
		world.setBlock(i + 10, j + 5, k + 10, Elysium.blockPalestoneBrick.blockID);
		world.setBlock(i + 10, j + 5, k + 11, Block.stairsStoneBrick.blockID, 3, 1);
		world.setBlock(i + 10, j + 6, k + 1, Block.stairsStoneBrick.blockID, 2, 1);
		world.setBlock(i + 10, j + 6, k + 2, Elysium.blockPalestoneBrick.blockID);
		world.setBlock(i + 10, j + 6, k + 9, Elysium.blockPalestoneBrick.blockID);
		world.setBlock(i + 10, j + 6, k + 10, Block.stairsStoneBrick.blockID, 3, 1);
		world.setBlock(i + 10, j + 7, k + 2, Block.stairsStoneBrick.blockID, 2, 1);
		world.setBlock(i + 10, j + 7, k + 3, Elysium.blockPalestoneBrick.blockID);
		world.setBlock(i + 10, j + 7, k + 8, Elysium.blockPalestoneBrick.blockID);
		world.setBlock(i + 10, j + 7, k + 9, Block.stairsStoneBrick.blockID, 3, 1);
		world.setBlock(i + 10, j + 8, k + 3, Block.stairsStoneBrick.blockID, 2, 1);
		world.setBlock(i + 10, j + 8, k + 4, Elysium.blockPalestoneBrick.blockID);
		world.setBlock(i + 10, j + 8, k + 7, Elysium.blockPalestoneBrick.blockID);
		world.setBlock(i + 10, j + 8, k + 8, Block.stairsStoneBrick.blockID, 3, 1);
		world.setBlock(i + 10, j + 9, k + 4, Block.stairsStoneBrick.blockID, 2, 1);
		world.setBlock(i + 10, j + 9, k + 5, Elysium.blockPalestoneBrick.blockID);
		world.setBlock(i + 10, j + 9, k + 6, Elysium.blockPalestoneBrick.blockID);
		world.setBlock(i + 10, j + 9, k + 7, Block.stairsStoneBrick.blockID, 3, 1);
		world.setBlock(i + 10, j + 10, k + 5, Block.stairsStoneBrick.blockID, 2, 1);
		world.setBlock(i + 10, j + 10, k + 6, Block.stairsStoneBrick.blockID, 3, 1);
		world.setBlock(i + 11, j + 0, k + 0, Block.grass.blockID);
		world.setBlock(i + 11, j + 0, k + 1, Elysium.blockPalestoneBrick.blockID);
		world.setBlock(i + 11, j + 0, k + 2, Elysium.blockPalestoneBrick.blockID);
		world.setBlock(i + 11, j + 0, k + 3, Elysium.blockPalestonePillar.blockID);
		world.setBlock(i + 11, j + 0, k + 4, Elysium.blockPalestoneBrick.blockID);
		world.setBlock(i + 11, j + 0, k + 5, Elysium.blockPalestonePillar.blockID);
		world.setBlock(i + 11, j + 0, k + 6, Elysium.blockPalestoneBrick.blockID);
		world.setBlock(i + 11, j + 0, k + 7, Elysium.blockPalestonePillar.blockID);
		world.setBlock(i + 11, j + 0, k + 8, Elysium.blockPalestoneBrick.blockID);
		world.setBlock(i + 11, j + 0, k + 9, Elysium.blockPalestonePillar.blockID);
		world.setBlock(i + 11, j + 0, k + 10, Elysium.blockPalestoneBrick.blockID);
		world.setBlock(i + 11, j + 0, k + 11, Block.grass.blockID);
		world.setBlock(i + 11, j + 1, k + 1, Elysium.blockPalestoneBrick.blockID);
		world.setBlock(i + 11, j + 1, k + 10, Elysium.blockPalestoneBrick.blockID);
		world.setBlock(i + 11, j + 2, k + 1, Elysium.blockPalestoneBrick.blockID);
		world.setBlock(i + 11, j + 2, k + 10, Elysium.blockPalestoneBrick.blockID);
		world.setBlock(i + 11, j + 3, k + 1, Elysium.blockPalestoneBrick.blockID);
		world.setBlock(i + 11, j + 3, k + 10, Elysium.blockPalestoneBrick.blockID);
		world.setBlock(i + 11, j + 4, k + 1, Elysium.blockPalestoneBrick.blockID);
		world.setBlock(i + 11, j + 4, k + 10, Elysium.blockPalestoneBrick.blockID);
		world.setBlock(i + 11, j + 5, k + 0, Block.stairsStoneBrick.blockID, 2, 1);
		world.setBlock(i + 11, j + 5, k + 1, Elysium.blockPalestoneBrick.blockID);
		world.setBlock(i + 11, j + 5, k + 2, Elysium.blockPalestoneBrick.blockID);
		world.setBlock(i + 11, j + 5, k + 3, Elysium.blockPalestoneBrick.blockID);
		world.setBlock(i + 11, j + 5, k + 4, Elysium.blockPalestoneBrick.blockID);
		world.setBlock(i + 11, j + 5, k + 5, Elysium.blockPalestoneBrick.blockID);
		world.setBlock(i + 11, j + 5, k + 6, Elysium.blockPalestoneBrick.blockID);
		world.setBlock(i + 11, j + 5, k + 7, Elysium.blockPalestoneBrick.blockID);
		world.setBlock(i + 11, j + 5, k + 8, Elysium.blockPalestoneBrick.blockID);
		world.setBlock(i + 11, j + 5, k + 9, Elysium.blockPalestoneBrick.blockID);
		world.setBlock(i + 11, j + 5, k + 10, Elysium.blockPalestoneBrick.blockID);
		world.setBlock(i + 11, j + 5, k + 11, Block.stairsStoneBrick.blockID, 3, 1);
		world.setBlock(i + 11, j + 6, k + 1, Block.stairsStoneBrick.blockID, 2, 1);
		world.setBlock(i + 11, j + 6, k + 2, Elysium.blockPalestoneBrick.blockID);
		world.setBlock(i + 11, j + 6, k + 9, Elysium.blockPalestoneBrick.blockID);
		world.setBlock(i + 11, j + 6, k + 10, Block.stairsStoneBrick.blockID, 3, 1);
		world.setBlock(i + 11, j + 7, k + 2, Block.stairsStoneBrick.blockID, 2, 1);
		world.setBlock(i + 11, j + 7, k + 3, Elysium.blockPalestoneBrick.blockID);
		world.setBlock(i + 11, j + 7, k + 8, Elysium.blockPalestoneBrick.blockID);
		world.setBlock(i + 11, j + 7, k + 9, Block.stairsStoneBrick.blockID, 3, 1);
		world.setBlock(i + 11, j + 8, k + 3, Block.stairsStoneBrick.blockID, 2, 1);
		world.setBlock(i + 11, j + 8, k + 4, Elysium.blockPalestoneBrick.blockID);
		world.setBlock(i + 11, j + 8, k + 7, Elysium.blockPalestoneBrick.blockID);
		world.setBlock(i + 11, j + 8, k + 8, Block.stairsStoneBrick.blockID, 3, 1);
		world.setBlock(i + 11, j + 9, k + 4, Block.stairsStoneBrick.blockID, 2, 1);
		world.setBlock(i + 11, j + 9, k + 5, Elysium.blockPalestoneBrick.blockID);
		world.setBlock(i + 11, j + 9, k + 6, Elysium.blockPalestoneBrick.blockID);
		world.setBlock(i + 11, j + 9, k + 7, Block.stairsStoneBrick.blockID, 3, 1);
		world.setBlock(i + 11, j + 10, k + 5, Block.stairsStoneBrick.blockID, 2, 1);
		world.setBlock(i + 11, j + 10, k + 6, Block.stairsStoneBrick.blockID, 3, 1);
		world.setBlock(i + 12, j + 0, k + 0, Block.grass.blockID);
		world.setBlock(i + 12, j + 0, k + 1, Elysium.blockPalestoneBrick.blockID);
		world.setBlock(i + 12, j + 0, k + 2, Elysium.blockPalestonePillar.blockID);
		world.setBlock(i + 12, j + 0, k + 3, Elysium.blockPalestoneBrick.blockID);
		world.setBlock(i + 12, j + 0, k + 4, Elysium.blockPalestonePillar.blockID);
		world.setBlock(i + 12, j + 0, k + 5, Elysium.blockPalestoneBrick.blockID);
		world.setBlock(i + 12, j + 0, k + 6, Elysium.blockPalestonePillar.blockID);
		world.setBlock(i + 12, j + 0, k + 7, Elysium.blockPalestoneBrick.blockID);
		world.setBlock(i + 12, j + 0, k + 8, Elysium.blockPalestonePillar.blockID);
		world.setBlock(i + 12, j + 0, k + 9, Elysium.blockPalestoneBrick.blockID);
		world.setBlock(i + 12, j + 0, k + 10, Elysium.blockPalestoneBrick.blockID);
		world.setBlock(i + 12, j + 0, k + 11, Block.grass.blockID);
		world.setBlock(i + 12, j + 1, k + 1, Elysium.blockPalestoneBrick.blockID);
		world.setBlock(i + 12, j + 1, k + 10, Elysium.blockPalestoneBrick.blockID);
		world.setBlock(i + 12, j + 2, k + 1, Elysium.blockPalestoneBrick.blockID);
		world.setBlock(i + 12, j + 2, k + 10, Elysium.blockPalestoneBrick.blockID);
		world.setBlock(i + 12, j + 3, k + 1, Elysium.blockPalestoneBrick.blockID);
		world.setBlock(i + 12, j + 3, k + 10, Elysium.blockPalestoneBrick.blockID);
		world.setBlock(i + 12, j + 4, k + 1, Elysium.blockPalestoneBrick.blockID);
		world.setBlock(i + 12, j + 4, k + 10, Elysium.blockPalestoneBrick.blockID);
		world.setBlock(i + 12, j + 5, k + 0, Block.stairsStoneBrick.blockID, 2, 1);
		world.setBlock(i + 12, j + 5, k + 1, Elysium.blockPalestoneBrick.blockID);
		world.setBlock(i + 12, j + 5, k + 2, Elysium.blockPalestoneBrick.blockID);
		world.setBlock(i + 12, j + 5, k + 3, Elysium.blockPalestoneBrick.blockID);
		world.setBlock(i + 12, j + 5, k + 4, Elysium.blockPalestoneBrick.blockID);
		world.setBlock(i + 12, j + 5, k + 5, Elysium.blockPalestoneBrick.blockID);
		world.setBlock(i + 12, j + 5, k + 6, Elysium.blockPalestoneBrick.blockID);
		world.setBlock(i + 12, j + 5, k + 7, Elysium.blockPalestoneBrick.blockID);
		world.setBlock(i + 12, j + 5, k + 8, Elysium.blockPalestoneBrick.blockID);
		world.setBlock(i + 12, j + 5, k + 9, Elysium.blockPalestoneBrick.blockID);
		world.setBlock(i + 12, j + 5, k + 10, Elysium.blockPalestoneBrick.blockID);
		world.setBlock(i + 12, j + 5, k + 11, Block.stairsStoneBrick.blockID, 3, 1);
		world.setBlock(i + 12, j + 6, k + 1, Block.stairsStoneBrick.blockID, 2, 1);
		world.setBlock(i + 12, j + 6, k + 2, Elysium.blockPalestoneBrick.blockID);
		world.setBlock(i + 12, j + 6, k + 9, Elysium.blockPalestoneBrick.blockID);
		world.setBlock(i + 12, j + 6, k + 10, Block.stairsStoneBrick.blockID, 3, 1);
		world.setBlock(i + 12, j + 7, k + 2, Block.stairsStoneBrick.blockID, 2, 1);
		world.setBlock(i + 12, j + 7, k + 3, Elysium.blockPalestoneBrick.blockID);
		world.setBlock(i + 12, j + 7, k + 8, Elysium.blockPalestoneBrick.blockID);
		world.setBlock(i + 12, j + 7, k + 9, Block.stairsStoneBrick.blockID, 3, 1);
		world.setBlock(i + 12, j + 8, k + 3, Block.stairsStoneBrick.blockID, 2, 1);
		world.setBlock(i + 12, j + 8, k + 4, Elysium.blockPalestoneBrick.blockID);
		world.setBlock(i + 12, j + 8, k + 7, Elysium.blockPalestoneBrick.blockID);
		world.setBlock(i + 12, j + 8, k + 8, Block.stairsStoneBrick.blockID, 3, 1);
		world.setBlock(i + 12, j + 9, k + 4, Block.stairsStoneBrick.blockID, 2, 1);
		world.setBlock(i + 12, j + 9, k + 5, Elysium.blockPalestoneBrick.blockID);
		world.setBlock(i + 12, j + 9, k + 6, Elysium.blockPalestoneBrick.blockID);
		world.setBlock(i + 12, j + 9, k + 7, Block.stairsStoneBrick.blockID, 3, 1);
		world.setBlock(i + 12, j + 10, k + 5, Block.stairsStoneBrick.blockID, 2, 1);
		world.setBlock(i + 12, j + 10, k + 6, Block.stairsStoneBrick.blockID, 3, 1);
		world.setBlock(i + 13, j + 0, k + 0, Block.grass.blockID);
		world.setBlock(i + 13, j + 0, k + 1, Elysium.blockPalestoneBrick.blockID);
		world.setBlock(i + 13, j + 0, k + 2, Elysium.blockPalestoneBrick.blockID);
		world.setBlock(i + 13, j + 0, k + 3, Elysium.blockPalestonePillar.blockID);
		world.setBlock(i + 13, j + 0, k + 4, Elysium.blockPalestoneBrick.blockID);
		world.setBlock(i + 13, j + 0, k + 5, Elysium.blockPalestonePillar.blockID);
		world.setBlock(i + 13, j + 0, k + 6, Elysium.blockPalestoneBrick.blockID);
		world.setBlock(i + 13, j + 0, k + 7, Elysium.blockPalestonePillar.blockID);
		world.setBlock(i + 13, j + 0, k + 8, Elysium.blockPalestoneBrick.blockID);
		world.setBlock(i + 13, j + 0, k + 9, Elysium.blockPalestonePillar.blockID);
		world.setBlock(i + 13, j + 0, k + 10, Elysium.blockPalestoneBrick.blockID);
		world.setBlock(i + 13, j + 0, k + 11, Block.grass.blockID);
		world.setBlock(i + 13, j + 1, k + 1, Elysium.blockPalestoneBrick.blockID);
		world.setBlock(i + 13, j + 1, k + 10, Elysium.blockPalestoneBrick.blockID);
		world.setBlock(i + 13, j + 2, k + 1, Elysium.blockPalestoneBrick.blockID);
		world.setBlock(i + 13, j + 2, k + 10, Elysium.blockPalestoneBrick.blockID);
		world.setBlock(i + 13, j + 3, k + 1, Elysium.blockPalestoneBrick.blockID);
		world.setBlock(i + 13, j + 3, k + 10, Elysium.blockPalestoneBrick.blockID);
		world.setBlock(i + 13, j + 4, k + 1, Elysium.blockPalestoneBrick.blockID);
		world.setBlock(i + 13, j + 4, k + 10, Elysium.blockPalestoneBrick.blockID);
		world.setBlock(i + 13, j + 5, k + 0, Block.stairsStoneBrick.blockID, 2, 1);
		world.setBlock(i + 13, j + 5, k + 1, Elysium.blockPalestoneBrick.blockID);
		world.setBlock(i + 13, j + 5, k + 2, Elysium.blockPalestoneBrick.blockID);
		world.setBlock(i + 13, j + 5, k + 3, Elysium.blockPalestoneBrick.blockID);
		world.setBlock(i + 13, j + 5, k + 4, Elysium.blockPalestoneBrick.blockID);
		world.setBlock(i + 13, j + 5, k + 5, Elysium.blockPalestoneBrick.blockID);
		world.setBlock(i + 13, j + 5, k + 6, Elysium.blockPalestoneBrick.blockID);
		world.setBlock(i + 13, j + 5, k + 7, Elysium.blockPalestoneBrick.blockID);
		world.setBlock(i + 13, j + 5, k + 8, Elysium.blockPalestoneBrick.blockID);
		world.setBlock(i + 13, j + 5, k + 9, Elysium.blockPalestoneBrick.blockID);
		world.setBlock(i + 13, j + 5, k + 10, Elysium.blockPalestoneBrick.blockID);
		world.setBlock(i + 13, j + 5, k + 11, Block.stairsStoneBrick.blockID, 3, 1);
		world.setBlock(i + 13, j + 6, k + 1, Block.stairsStoneBrick.blockID, 2, 1);
		world.setBlock(i + 13, j + 6, k + 2, Elysium.blockPalestoneBrick.blockID);
		world.setBlock(i + 13, j + 6, k + 9, Elysium.blockPalestoneBrick.blockID);
		world.setBlock(i + 13, j + 6, k + 10, Block.stairsStoneBrick.blockID, 3, 1);
		world.setBlock(i + 13, j + 7, k + 2, Block.stairsStoneBrick.blockID, 2, 1);
		world.setBlock(i + 13, j + 7, k + 3, Elysium.blockPalestoneBrick.blockID);
		world.setBlock(i + 13, j + 7, k + 8, Elysium.blockPalestoneBrick.blockID);
		world.setBlock(i + 13, j + 7, k + 9, Block.stairsStoneBrick.blockID, 3, 1);
		world.setBlock(i + 13, j + 8, k + 3, Block.stairsStoneBrick.blockID, 2, 1);
		world.setBlock(i + 13, j + 8, k + 4, Elysium.blockPalestoneBrick.blockID);
		world.setBlock(i + 13, j + 8, k + 7, Elysium.blockPalestoneBrick.blockID);
		world.setBlock(i + 13, j + 8, k + 8, Block.stairsStoneBrick.blockID, 3, 1);
		world.setBlock(i + 13, j + 9, k + 4, Block.stairsStoneBrick.blockID, 2, 1);
		world.setBlock(i + 13, j + 9, k + 5, Elysium.blockPalestoneBrick.blockID);
		world.setBlock(i + 13, j + 9, k + 6, Elysium.blockPalestoneBrick.blockID);
		world.setBlock(i + 13, j + 9, k + 7, Block.stairsStoneBrick.blockID, 3, 1);
		world.setBlock(i + 13, j + 10, k + 5, Block.stairsStoneBrick.blockID, 2, 1);
		world.setBlock(i + 13, j + 10, k + 6, Block.stairsStoneBrick.blockID, 3, 1);
		world.setBlock(i + 14, j + 0, k + 0, Block.grass.blockID);
		world.setBlock(i + 14, j + 0, k + 1, Elysium.blockPalestoneBrick.blockID);
		world.setBlock(i + 14, j + 0, k + 2, Elysium.blockPalestonePillar.blockID);
		world.setBlock(i + 14, j + 0, k + 3, Elysium.blockPalestoneBrick.blockID);
		world.setBlock(i + 14, j + 0, k + 4, Elysium.blockPalestonePillar.blockID);
		world.setBlock(i + 14, j + 0, k + 5, Elysium.blockPalestoneBrick.blockID);
		world.setBlock(i + 14, j + 0, k + 6, Elysium.blockPalestonePillar.blockID);
		world.setBlock(i + 14, j + 0, k + 7, Elysium.blockPalestoneBrick.blockID);
		world.setBlock(i + 14, j + 0, k + 8, Elysium.blockPalestonePillar.blockID);
		world.setBlock(i + 14, j + 0, k + 9, Elysium.blockPalestoneBrick.blockID);
		world.setBlock(i + 14, j + 0, k + 10, Elysium.blockPalestoneBrick.blockID);
		world.setBlock(i + 14, j + 0, k + 11, Block.grass.blockID);
		world.setBlock(i + 14, j + 1, k + 1, Elysium.blockPalestoneBrick.blockID);
		world.setBlock(i + 14, j + 1, k + 10, Elysium.blockPalestoneBrick.blockID);
		world.setBlock(i + 14, j + 2, k + 1, Elysium.blockPalestoneBrick.blockID);
		world.setBlock(i + 14, j + 2, k + 10, Elysium.blockPalestoneBrick.blockID);
		world.setBlock(i + 14, j + 3, k + 1, Elysium.blockPalestoneBrick.blockID);
		world.setBlock(i + 14, j + 3, k + 10, Elysium.blockPalestoneBrick.blockID);
		world.setBlock(i + 14, j + 4, k + 1, Elysium.blockPalestoneBrick.blockID);
		world.setBlock(i + 14, j + 4, k + 10, Elysium.blockPalestoneBrick.blockID);
		world.setBlock(i + 14, j + 5, k + 0, Block.stairsStoneBrick.blockID, 2, 1);
		world.setBlock(i + 14, j + 5, k + 1, Elysium.blockPalestoneBrick.blockID);
		world.setBlock(i + 14, j + 5, k + 2, Elysium.blockPalestoneBrick.blockID);
		world.setBlock(i + 14, j + 5, k + 3, Elysium.blockPalestoneBrick.blockID);
		world.setBlock(i + 14, j + 5, k + 4, Elysium.blockPalestoneBrick.blockID);
		world.setBlock(i + 14, j + 5, k + 5, Elysium.blockPalestoneBrick.blockID);
		world.setBlock(i + 14, j + 5, k + 6, Elysium.blockPalestoneBrick.blockID);
		world.setBlock(i + 14, j + 5, k + 7, Elysium.blockPalestoneBrick.blockID);
		world.setBlock(i + 14, j + 5, k + 8, Elysium.blockPalestoneBrick.blockID);
		world.setBlock(i + 14, j + 5, k + 9, Elysium.blockPalestoneBrick.blockID);
		world.setBlock(i + 14, j + 5, k + 10, Elysium.blockPalestoneBrick.blockID);
		world.setBlock(i + 14, j + 5, k + 11, Block.stairsStoneBrick.blockID, 3, 1);
		world.setBlock(i + 14, j + 6, k + 1, Block.stairsStoneBrick.blockID, 2, 1);
		world.setBlock(i + 14, j + 6, k + 2, Elysium.blockPalestoneBrick.blockID);
		world.setBlock(i + 14, j + 6, k + 9, Elysium.blockPalestoneBrick.blockID);
		world.setBlock(i + 14, j + 6, k + 10, Block.stairsStoneBrick.blockID, 3, 1);
		world.setBlock(i + 14, j + 7, k + 2, Block.stairsStoneBrick.blockID, 2, 1);
		world.setBlock(i + 14, j + 7, k + 3, Elysium.blockPalestoneBrick.blockID);
		world.setBlock(i + 14, j + 7, k + 8, Elysium.blockPalestoneBrick.blockID);
		world.setBlock(i + 14, j + 7, k + 9, Block.stairsStoneBrick.blockID, 3, 1);
		world.setBlock(i + 14, j + 8, k + 3, Block.stairsStoneBrick.blockID, 2, 1);
		world.setBlock(i + 14, j + 8, k + 4, Elysium.blockPalestoneBrick.blockID);
		world.setBlock(i + 14, j + 8, k + 7, Elysium.blockPalestoneBrick.blockID);
		world.setBlock(i + 14, j + 8, k + 8, Block.stairsStoneBrick.blockID, 3, 1);
		world.setBlock(i + 14, j + 9, k + 4, Block.stairsStoneBrick.blockID, 2, 1);
		world.setBlock(i + 14, j + 9, k + 5, Elysium.blockPalestoneBrick.blockID);
		world.setBlock(i + 14, j + 9, k + 6, Elysium.blockPalestoneBrick.blockID);
		world.setBlock(i + 14, j + 9, k + 7, Block.stairsStoneBrick.blockID, 3, 1);
		world.setBlock(i + 14, j + 10, k + 5, Block.stairsStoneBrick.blockID, 2, 1);
		world.setBlock(i + 14, j + 10, k + 6, Block.stairsStoneBrick.blockID, 3, 1);
		world.setBlock(i + 15, j + 0, k + 0, Block.grass.blockID);
		world.setBlock(i + 15, j + 0, k + 1, Elysium.blockPalestoneBrick.blockID);
		world.setBlock(i + 15, j + 0, k + 2, Elysium.blockPalestoneBrick.blockID);
		world.setBlock(i + 15, j + 0, k + 3, Elysium.blockPalestonePillar.blockID);
		world.setBlock(i + 15, j + 0, k + 4, Elysium.blockPalestoneBrick.blockID);
		world.setBlock(i + 15, j + 0, k + 5, Elysium.blockPalestonePillar.blockID);
		world.setBlock(i + 15, j + 0, k + 6, Elysium.blockPalestoneBrick.blockID);
		world.setBlock(i + 15, j + 0, k + 7, Elysium.blockPalestonePillar.blockID);
		world.setBlock(i + 15, j + 0, k + 8, Elysium.blockPalestoneBrick.blockID);
		world.setBlock(i + 15, j + 0, k + 9, Elysium.blockPalestonePillar.blockID);
		world.setBlock(i + 15, j + 0, k + 10, Elysium.blockPalestoneBrick.blockID);
		world.setBlock(i + 15, j + 0, k + 11, Block.grass.blockID);
		world.setBlock(i + 15, j + 1, k + 1, Elysium.blockPalestoneBrick.blockID);
		world.setBlock(i + 15, j + 1, k + 10, Elysium.blockPalestoneBrick.blockID);
		world.setBlock(i + 15, j + 2, k + 1, Elysium.blockPalestoneBrick.blockID);
		world.setBlock(i + 15, j + 2, k + 10, Elysium.blockPalestoneBrick.blockID);
		world.setBlock(i + 15, j + 3, k + 1, Elysium.blockPalestoneBrick.blockID);
		world.setBlock(i + 15, j + 3, k + 10, Elysium.blockPalestoneBrick.blockID);
		world.setBlock(i + 15, j + 4, k + 1, Elysium.blockPalestoneBrick.blockID);
		world.setBlock(i + 15, j + 4, k + 10, Elysium.blockPalestoneBrick.blockID);
		world.setBlock(i + 15, j + 5, k + 0, Block.stairsStoneBrick.blockID, 2, 1);
		world.setBlock(i + 15, j + 5, k + 1, Elysium.blockPalestoneBrick.blockID);
		world.setBlock(i + 15, j + 5, k + 2, Elysium.blockPalestoneBrick.blockID);
		world.setBlock(i + 15, j + 5, k + 3, Elysium.blockPalestoneBrick.blockID);
		world.setBlock(i + 15, j + 5, k + 4, Elysium.blockPalestoneBrick.blockID);
		world.setBlock(i + 15, j + 5, k + 5, Elysium.blockPalestoneBrick.blockID);
		world.setBlock(i + 15, j + 5, k + 6, Elysium.blockPalestoneBrick.blockID);
		world.setBlock(i + 15, j + 5, k + 7, Elysium.blockPalestoneBrick.blockID);
		world.setBlock(i + 15, j + 5, k + 8, Elysium.blockPalestoneBrick.blockID);
		world.setBlock(i + 15, j + 5, k + 9, Elysium.blockPalestoneBrick.blockID);
		world.setBlock(i + 15, j + 5, k + 10, Elysium.blockPalestoneBrick.blockID);
		world.setBlock(i + 15, j + 5, k + 11, Block.stairsStoneBrick.blockID, 3, 1);
		world.setBlock(i + 15, j + 6, k + 1, Block.stairsStoneBrick.blockID, 2, 1);
		world.setBlock(i + 15, j + 6, k + 2, Elysium.blockPalestoneBrick.blockID);
		world.setBlock(i + 15, j + 6, k + 9, Elysium.blockPalestoneBrick.blockID);
		world.setBlock(i + 15, j + 6, k + 10, Block.stairsStoneBrick.blockID, 3, 1);
		world.setBlock(i + 15, j + 7, k + 2, Block.stairsStoneBrick.blockID, 2, 1);
		world.setBlock(i + 15, j + 7, k + 3, Elysium.blockPalestoneBrick.blockID);
		world.setBlock(i + 15, j + 7, k + 8, Elysium.blockPalestoneBrick.blockID);
		world.setBlock(i + 15, j + 7, k + 9, Block.stairsStoneBrick.blockID, 3, 1);
		world.setBlock(i + 15, j + 8, k + 3, Block.stairsStoneBrick.blockID, 2, 1);
		world.setBlock(i + 15, j + 8, k + 4, Elysium.blockPalestoneBrick.blockID);
		world.setBlock(i + 15, j + 8, k + 7, Elysium.blockPalestoneBrick.blockID);
		world.setBlock(i + 15, j + 8, k + 8, Block.stairsStoneBrick.blockID, 3, 1);
		world.setBlock(i + 15, j + 9, k + 4, Block.stairsStoneBrick.blockID, 2, 1);
		world.setBlock(i + 15, j + 9, k + 5, Elysium.blockPalestoneBrick.blockID);
		world.setBlock(i + 15, j + 9, k + 6, Elysium.blockPalestoneBrick.blockID);
		world.setBlock(i + 15, j + 9, k + 7, Block.stairsStoneBrick.blockID, 3, 1);
		world.setBlock(i + 15, j + 10, k + 5, Block.stairsStoneBrick.blockID, 2, 1);
		world.setBlock(i + 15, j + 10, k + 6, Block.stairsStoneBrick.blockID, 3, 1);
		world.setBlock(i + 16, j + 0, k + 0, Block.grass.blockID);
		world.setBlock(i + 16, j + 0, k + 1, Elysium.blockPalestoneBrick.blockID);
		world.setBlock(i + 16, j + 0, k + 2, Elysium.blockPalestoneBrick.blockID);
		world.setBlock(i + 16, j + 0, k + 3, Elysium.blockPalestoneBrick.blockID);
		world.setBlock(i + 16, j + 0, k + 4, Elysium.blockPalestoneBrick.blockID);
		world.setBlock(i + 16, j + 0, k + 5, -17);
		world.setBlock(i + 16, j + 0, k + 6, -17);
		world.setBlock(i + 16, j + 0, k + 7, Elysium.blockPalestoneBrick.blockID);
		world.setBlock(i + 16, j + 0, k + 8, Elysium.blockPalestoneBrick.blockID);
		world.setBlock(i + 16, j + 0, k + 9, Elysium.blockPalestoneBrick.blockID);
		world.setBlock(i + 16, j + 0, k + 10, Elysium.blockPalestoneBrick.blockID);
		world.setBlock(i + 16, j + 0, k + 11, Block.grass.blockID);
		world.setBlock(i + 16, j + 1, k + 1, Elysium.blockPalestoneBrickChiseld.blockID, 2, 1);
		world.setBlock(i + 16, j + 1, k + 2, Elysium.blockPalestoneBrick.blockID);
		world.setBlock(i + 16, j + 1, k + 3, Elysium.blockPalestoneBrick.blockID);
		world.setBlock(i + 16, j + 1, k + 4, Elysium.blockPalestoneBrick.blockID);
		world.setBlock(i + 16, j + 1, k + 7, Elysium.blockPalestoneBrick.blockID);
		world.setBlock(i + 16, j + 1, k + 8, Elysium.blockPalestoneBrick.blockID);
		world.setBlock(i + 16, j + 1, k + 9, Elysium.blockPalestoneBrick.blockID);
		world.setBlock(i + 16, j + 1, k + 10, Elysium.blockPalestoneBrickChiseld.blockID, 2, 1);
		world.setBlock(i + 16, j + 2, k + 1, Elysium.blockPalestoneBrickChiseld.blockID, 2, 1);
		world.setBlock(i + 16, j + 2, k + 2, Elysium.blockPalestoneBrick.blockID);
		world.setBlock(i + 16, j + 2, k + 3, Elysium.blockPalestoneBrick.blockID);
		world.setBlock(i + 16, j + 2, k + 4, Elysium.blockPalestoneBrick.blockID);
		world.setBlock(i + 16, j + 2, k + 7, Elysium.blockPalestoneBrick.blockID);
		world.setBlock(i + 16, j + 2, k + 8, Elysium.blockPalestoneBrick.blockID);
		world.setBlock(i + 16, j + 2, k + 9, Elysium.blockPalestoneBrick.blockID);
		world.setBlock(i + 16, j + 2, k + 10, Elysium.blockPalestoneBrickChiseld.blockID, 2, 1);
		world.setBlock(i + 16, j + 3, k + 1, Elysium.blockPalestoneBrickChiseld.blockID, 2, 1);
		world.setBlock(i + 16, j + 3, k + 2, Elysium.blockPalestoneBrick.blockID);
		world.setBlock(i + 16, j + 3, k + 3, Elysium.blockPalestoneBrick.blockID);
		world.setBlock(i + 16, j + 3, k + 4, Elysium.blockPalestoneBrick.blockID);
		world.setBlock(i + 16, j + 3, k + 5, Elysium.blockPalestoneBrick.blockID);
		world.setBlock(i + 16, j + 3, k + 6, Elysium.blockPalestoneBrick.blockID);
		world.setBlock(i + 16, j + 3, k + 7, Elysium.blockPalestoneBrick.blockID);
		world.setBlock(i + 16, j + 3, k + 8, Elysium.blockPalestoneBrick.blockID);
		world.setBlock(i + 16, j + 3, k + 9, Elysium.blockPalestoneBrick.blockID);
		world.setBlock(i + 16, j + 3, k + 10, Elysium.blockPalestoneBrickChiseld.blockID, 2, 1);
		world.setBlock(i + 16, j + 4, k + 1, Elysium.blockPalestoneBrickChiseld.blockID, 2, 1);
		world.setBlock(i + 16, j + 4, k + 2, Elysium.blockPalestoneBrick.blockID);
		world.setBlock(i + 16, j + 4, k + 3, Elysium.blockPalestoneBrick.blockID);
		world.setBlock(i + 16, j + 4, k + 4, Elysium.blockPalestoneBrick.blockID);
		world.setBlock(i + 16, j + 4, k + 5, Elysium.blockPalestoneBrick.blockID);
		world.setBlock(i + 16, j + 4, k + 6, Elysium.blockPalestoneBrick.blockID);
		world.setBlock(i + 16, j + 4, k + 7, Elysium.blockPalestoneBrick.blockID);
		world.setBlock(i + 16, j + 4, k + 8, Elysium.blockPalestoneBrick.blockID);
		world.setBlock(i + 16, j + 4, k + 9, Elysium.blockPalestoneBrick.blockID);
		world.setBlock(i + 16, j + 4, k + 10, Elysium.blockPalestoneBrickChiseld.blockID, 2, 1);
		world.setBlock(i + 16, j + 5, k + 0, Block.stairsStoneBrick.blockID, 2, 1);
		world.setBlock(i + 16, j + 5, k + 1, Elysium.blockPalestoneBrick.blockID);
		world.setBlock(i + 16, j + 5, k + 2, Elysium.blockPalestoneBrick.blockID);
		world.setBlock(i + 16, j + 5, k + 3, Elysium.blockPalestoneBrick.blockID);
		world.setBlock(i + 16, j + 5, k + 4, Elysium.blockPalestoneBrick.blockID);
		world.setBlock(i + 16, j + 5, k + 5, Elysium.blockPalestoneBrick.blockID);
		world.setBlock(i + 16, j + 5, k + 6, Elysium.blockPalestoneBrick.blockID);
		world.setBlock(i + 16, j + 5, k + 7, Elysium.blockPalestoneBrick.blockID);
		world.setBlock(i + 16, j + 5, k + 8, Elysium.blockPalestoneBrick.blockID);
		world.setBlock(i + 16, j + 5, k + 9, Elysium.blockPalestoneBrick.blockID);
		world.setBlock(i + 16, j + 5, k + 10, Elysium.blockPalestoneBrick.blockID);
		world.setBlock(i + 16, j + 5, k + 11, Block.stairsStoneBrick.blockID, 3, 1);
		world.setBlock(i + 16, j + 6, k + 1, Block.stairsStoneBrick.blockID, 2, 1);
		world.setBlock(i + 16, j + 6, k + 2, Elysium.blockPalestoneBrick.blockID);
		world.setBlock(i + 16, j + 6, k + 9, Elysium.blockPalestoneBrick.blockID);
		world.setBlock(i + 16, j + 6, k + 10, Block.stairsStoneBrick.blockID, 3, 1);
		world.setBlock(i + 16, j + 7, k + 2, Block.stairsStoneBrick.blockID, 2, 1);
		world.setBlock(i + 16, j + 7, k + 3, Elysium.blockPalestoneBrick.blockID);
		world.setBlock(i + 16, j + 7, k + 8, Elysium.blockPalestoneBrick.blockID);
		world.setBlock(i + 16, j + 7, k + 9, Block.stairsStoneBrick.blockID, 3, 1);
		world.setBlock(i + 16, j + 8, k + 3, Block.stairsStoneBrick.blockID, 2, 1);
		world.setBlock(i + 16, j + 8, k + 4, Elysium.blockPalestoneBrick.blockID);
		world.setBlock(i + 16, j + 8, k + 7, Elysium.blockPalestoneBrick.blockID);
		world.setBlock(i + 16, j + 8, k + 8, Block.stairsStoneBrick.blockID, 3, 1);
		world.setBlock(i + 16, j + 9, k + 4, Block.stairsStoneBrick.blockID, 2, 1);
		world.setBlock(i + 16, j + 9, k + 5, Elysium.blockPalestoneBrick.blockID);
		world.setBlock(i + 16, j + 9, k + 6, Elysium.blockPalestoneBrick.blockID);
		world.setBlock(i + 16, j + 9, k + 7, Block.stairsStoneBrick.blockID, 3, 1);
		world.setBlock(i + 16, j + 10, k + 5, Block.stairsStoneBrick.blockID, 2, 1);
		world.setBlock(i + 16, j + 10, k + 6, Block.stairsStoneBrick.blockID, 3, 1);
		world.setBlock(i + 17, j + 0, k + 0, Block.grass.blockID);
		world.setBlock(i + 17, j + 0, k + 1, Elysium.blockPalestoneBrick.blockID);
		world.setBlock(i + 17, j + 0, k + 2, Elysium.blockPalestoneBrick.blockID);
		world.setBlock(i + 17, j + 0, k + 3, Elysium.blockPalestoneBrick.blockID);
		world.setBlock(i + 17, j + 0, k + 4, Elysium.blockPalestoneBrick.blockID);
		world.setBlock(i + 17, j + 0, k + 5, -17);
		world.setBlock(i + 17, j + 0, k + 6, -17);
		world.setBlock(i + 17, j + 0, k + 7, Elysium.blockPalestoneBrick.blockID);
		world.setBlock(i + 17, j + 0, k + 8, Elysium.blockPalestoneBrick.blockID);
		world.setBlock(i + 17, j + 0, k + 9, Elysium.blockPalestoneBrick.blockID);
		world.setBlock(i + 17, j + 0, k + 10, Elysium.blockPalestoneBrick.blockID);
		world.setBlock(i + 17, j + 0, k + 11, Block.grass.blockID);
		world.setBlock(i + 17, j + 5, k + 0, Block.stairsStoneBrick.blockID, 2, 1);
		world.setBlock(i + 17, j + 5, k + 1, Elysium.blockPalestoneBrick.blockID);
		world.setBlock(i + 17, j + 5, k + 2, Elysium.blockPalestoneBrick.blockID);
		world.setBlock(i + 17, j + 5, k + 3, Elysium.blockPalestoneBrick.blockID);
		world.setBlock(i + 17, j + 5, k + 4, Elysium.blockPalestoneBrick.blockID);
		world.setBlock(i + 17, j + 5, k + 5, Elysium.blockPalestoneBrick.blockID);
		world.setBlock(i + 17, j + 5, k + 6, Elysium.blockPalestoneBrick.blockID);
		world.setBlock(i + 17, j + 5, k + 7, Elysium.blockPalestoneBrick.blockID);
		world.setBlock(i + 17, j + 5, k + 8, Elysium.blockPalestoneBrick.blockID);
		world.setBlock(i + 17, j + 5, k + 9, Elysium.blockPalestoneBrick.blockID);
		world.setBlock(i + 17, j + 5, k + 10, Elysium.blockPalestoneBrick.blockID);
		world.setBlock(i + 17, j + 5, k + 11, Block.stairsStoneBrick.blockID, 3, 1);
		world.setBlock(i + 17, j + 6, k + 1, Block.stairsStoneBrick.blockID, 2, 1);
		world.setBlock(i + 17, j + 6, k + 2, Elysium.blockPalestoneBrick.blockID);
		world.setBlock(i + 17, j + 6, k + 9, Elysium.blockPalestoneBrick.blockID);
		world.setBlock(i + 17, j + 6, k + 10, Block.stairsStoneBrick.blockID, 3, 1);
		world.setBlock(i + 17, j + 7, k + 2, Block.stairsStoneBrick.blockID, 2, 1);
		world.setBlock(i + 17, j + 7, k + 3, Elysium.blockPalestoneBrick.blockID);
		world.setBlock(i + 17, j + 7, k + 8, Elysium.blockPalestoneBrick.blockID);
		world.setBlock(i + 17, j + 7, k + 9, Block.stairsStoneBrick.blockID, 3, 1);
		world.setBlock(i + 17, j + 8, k + 3, Block.stairsStoneBrick.blockID, 2, 1);
		world.setBlock(i + 17, j + 8, k + 4, Elysium.blockPalestoneBrick.blockID);
		world.setBlock(i + 17, j + 8, k + 7, Elysium.blockPalestoneBrick.blockID);
		world.setBlock(i + 17, j + 8, k + 8, Block.stairsStoneBrick.blockID, 3, 1);
		world.setBlock(i + 17, j + 9, k + 4, Block.stairsStoneBrick.blockID, 2, 1);
		world.setBlock(i + 17, j + 9, k + 5, Elysium.blockPalestoneBrick.blockID);
		world.setBlock(i + 17, j + 9, k + 6, Elysium.blockPalestoneBrick.blockID);
		world.setBlock(i + 17, j + 9, k + 7, Block.stairsStoneBrick.blockID, 3, 1);
		world.setBlock(i + 17, j + 10, k + 5, Block.stairsStoneBrick.blockID, 2, 1);
		world.setBlock(i + 17, j + 10, k + 6, Block.stairsStoneBrick.blockID, 3, 1);
		world.setBlock(i + 18, j + 0, k + 0, Block.grass.blockID);
		world.setBlock(i + 18, j + 0, k + 1, Elysium.blockPalestoneBrick.blockID);
		world.setBlock(i + 18, j + 0, k + 2, Elysium.blockPalestoneBrick.blockID);
		world.setBlock(i + 18, j + 0, k + 3, Elysium.blockPalestoneBrick.blockID);
		world.setBlock(i + 18, j + 0, k + 4, Elysium.blockPalestoneBrick.blockID);
		world.setBlock(i + 18, j + 0, k + 5, -17);
		world.setBlock(i + 18, j + 0, k + 6, -17);
		world.setBlock(i + 18, j + 0, k + 7, Elysium.blockPalestoneBrick.blockID);
		world.setBlock(i + 18, j + 0, k + 8, Elysium.blockPalestoneBrick.blockID);
		world.setBlock(i + 18, j + 0, k + 9, Elysium.blockPalestoneBrick.blockID);
		world.setBlock(i + 18, j + 0, k + 10, Elysium.blockPalestoneBrick.blockID);
		world.setBlock(i + 18, j + 0, k + 11, Block.grass.blockID);
		world.setBlock(i + 18, j + 5, k + 0, Block.stairsStoneBrick.blockID, 2, 1);
		world.setBlock(i + 18, j + 5, k + 1, Elysium.blockPalestoneBrick.blockID);
		world.setBlock(i + 18, j + 5, k + 2, Elysium.blockPalestoneBrick.blockID);
		world.setBlock(i + 18, j + 5, k + 3, Elysium.blockPalestoneBrick.blockID);
		world.setBlock(i + 18, j + 5, k + 4, Elysium.blockPalestoneBrick.blockID);
		world.setBlock(i + 18, j + 5, k + 5, Elysium.blockPalestoneBrick.blockID);
		world.setBlock(i + 18, j + 5, k + 6, Elysium.blockPalestoneBrick.blockID);
		world.setBlock(i + 18, j + 5, k + 7, Elysium.blockPalestoneBrick.blockID);
		world.setBlock(i + 18, j + 5, k + 8, Elysium.blockPalestoneBrick.blockID);
		world.setBlock(i + 18, j + 5, k + 9, Elysium.blockPalestoneBrick.blockID);
		world.setBlock(i + 18, j + 5, k + 10, Elysium.blockPalestoneBrick.blockID);
		world.setBlock(i + 18, j + 5, k + 11, Block.stairsStoneBrick.blockID, 3, 1);
		world.setBlock(i + 18, j + 6, k + 1, Block.stairsStoneBrick.blockID, 2, 1);
		world.setBlock(i + 18, j + 6, k + 2, Elysium.blockPalestoneBrick.blockID);
		world.setBlock(i + 18, j + 6, k + 9, Elysium.blockPalestoneBrick.blockID);
		world.setBlock(i + 18, j + 6, k + 10, Block.stairsStoneBrick.blockID, 3, 1);
		world.setBlock(i + 18, j + 7, k + 2, Block.stairsStoneBrick.blockID, 2, 1);
		world.setBlock(i + 18, j + 7, k + 3, Elysium.blockPalestoneBrick.blockID);
		world.setBlock(i + 18, j + 7, k + 8, Elysium.blockPalestoneBrick.blockID);
		world.setBlock(i + 18, j + 7, k + 9, Block.stairsStoneBrick.blockID, 3, 1);
		world.setBlock(i + 18, j + 8, k + 3, Block.stairsStoneBrick.blockID, 2, 1);
		world.setBlock(i + 18, j + 8, k + 4, Elysium.blockPalestoneBrick.blockID);
		world.setBlock(i + 18, j + 8, k + 7, Elysium.blockPalestoneBrick.blockID);
		world.setBlock(i + 18, j + 8, k + 8, Block.stairsStoneBrick.blockID, 3, 1);
		world.setBlock(i + 18, j + 9, k + 4, Block.stairsStoneBrick.blockID, 2, 1);
		world.setBlock(i + 18, j + 9, k + 5, Elysium.blockPalestoneBrick.blockID);
		world.setBlock(i + 18, j + 9, k + 6, Elysium.blockPalestoneBrick.blockID);
		world.setBlock(i + 18, j + 9, k + 7, Block.stairsStoneBrick.blockID, 3, 1);
		world.setBlock(i + 18, j + 10, k + 5, Block.stairsStoneBrick.blockID, 2, 1);
		world.setBlock(i + 18, j + 10, k + 6, Block.stairsStoneBrick.blockID, 3, 1);
		world.setBlock(i + 19, j + 0, k + 0, Block.grass.blockID);
		world.setBlock(i + 19, j + 0, k + 1, Elysium.blockPalestoneBrick.blockID);
		world.setBlock(i + 19, j + 0, k + 2, Elysium.blockPalestoneBrick.blockID);
		world.setBlock(i + 19, j + 0, k + 3, Elysium.blockPalestoneBrick.blockID);
		world.setBlock(i + 19, j + 0, k + 4, -17);
		world.setBlock(i + 19, j + 0, k + 5, -17);
		world.setBlock(i + 19, j + 0, k + 6, -17);
		world.setBlock(i + 19, j + 0, k + 7, -17);
		world.setBlock(i + 19, j + 0, k + 8, Elysium.blockPalestoneBrick.blockID);
		world.setBlock(i + 19, j + 0, k + 9, Elysium.blockPalestoneBrick.blockID);
		world.setBlock(i + 19, j + 0, k + 10, Elysium.blockPalestoneBrick.blockID);
		world.setBlock(i + 19, j + 0, k + 11, Block.grass.blockID);
		world.setBlock(i + 19, j + 5, k + 0, Block.stairsStoneBrick.blockID, 2, 1);
		world.setBlock(i + 19, j + 5, k + 1, Elysium.blockPalestoneBrick.blockID);
		world.setBlock(i + 19, j + 5, k + 2, Elysium.blockPalestoneBrick.blockID);
		world.setBlock(i + 19, j + 5, k + 3, Elysium.blockPalestoneBrick.blockID);
		world.setBlock(i + 19, j + 5, k + 4, Elysium.blockPalestoneBrick.blockID);
		world.setBlock(i + 19, j + 5, k + 5, Elysium.blockPalestoneBrick.blockID);
		world.setBlock(i + 19, j + 5, k + 6, Elysium.blockPalestoneBrick.blockID);
		world.setBlock(i + 19, j + 5, k + 7, Elysium.blockPalestoneBrick.blockID);
		world.setBlock(i + 19, j + 5, k + 8, Elysium.blockPalestoneBrick.blockID);
		world.setBlock(i + 19, j + 5, k + 9, Elysium.blockPalestoneBrick.blockID);
		world.setBlock(i + 19, j + 5, k + 10, Elysium.blockPalestoneBrick.blockID);
		world.setBlock(i + 19, j + 5, k + 11, Block.stairsStoneBrick.blockID, 3, 1);
		world.setBlock(i + 19, j + 6, k + 1, Block.stairsStoneBrick.blockID, 2, 1);
		world.setBlock(i + 19, j + 6, k + 2, Elysium.blockPalestoneBrick.blockID);
		world.setBlock(i + 19, j + 6, k + 9, Elysium.blockPalestoneBrick.blockID);
		world.setBlock(i + 19, j + 6, k + 10, Block.stairsStoneBrick.blockID, 3, 1);
		world.setBlock(i + 19, j + 7, k + 2, Block.stairsStoneBrick.blockID, 2, 1);
		world.setBlock(i + 19, j + 7, k + 3, Elysium.blockPalestoneBrick.blockID);
		world.setBlock(i + 19, j + 7, k + 8, Elysium.blockPalestoneBrick.blockID);
		world.setBlock(i + 19, j + 7, k + 9, Block.stairsStoneBrick.blockID, 3, 1);
		world.setBlock(i + 19, j + 8, k + 3, Block.stairsStoneBrick.blockID, 2, 1);
		world.setBlock(i + 19, j + 8, k + 4, Elysium.blockPalestoneBrick.blockID);
		world.setBlock(i + 19, j + 8, k + 7, Elysium.blockPalestoneBrick.blockID);
		world.setBlock(i + 19, j + 8, k + 8, Block.stairsStoneBrick.blockID, 3, 1);
		world.setBlock(i + 19, j + 9, k + 4, Block.stairsStoneBrick.blockID, 2, 1);
		world.setBlock(i + 19, j + 9, k + 5, Elysium.blockPalestoneBrick.blockID);
		world.setBlock(i + 19, j + 9, k + 6, Elysium.blockPalestoneBrick.blockID);
		world.setBlock(i + 19, j + 9, k + 7, Block.stairsStoneBrick.blockID, 3, 1);
		world.setBlock(i + 19, j + 10, k + 5, Block.stairsStoneBrick.blockID, 2, 1);
		world.setBlock(i + 19, j + 10, k + 6, Block.stairsStoneBrick.blockID, 3, 1);
		world.setBlock(i + 20, j + 0, k + 0, Block.grass.blockID);
		world.setBlock(i + 20, j + 0, k + 1, Elysium.blockPalestoneBrick.blockID);
		world.setBlock(i + 20, j + 0, k + 2, Elysium.blockPalestoneBrick.blockID);
		world.setBlock(i + 20, j + 0, k + 3, Elysium.blockPalestoneBrick.blockID);
		world.setBlock(i + 20, j + 0, k + 4, -17);
		world.setBlock(i + 20, j + 0, k + 5, -17);
		world.setBlock(i + 20, j + 0, k + 6, -17);
		world.setBlock(i + 20, j + 0, k + 7, -17);
		world.setBlock(i + 20, j + 0, k + 8, Elysium.blockPalestoneBrick.blockID);
		world.setBlock(i + 20, j + 0, k + 9, Elysium.blockPalestoneBrick.blockID);
		world.setBlock(i + 20, j + 0, k + 10, Elysium.blockPalestoneBrick.blockID);
		world.setBlock(i + 20, j + 0, k + 11, Block.grass.blockID);
		world.setBlock(i + 20, j + 1, k + 1, Elysium.blockPalestoneBrickChiseld.blockID, 2, 1);
		world.setBlock(i + 20, j + 1, k + 10, Elysium.blockPalestoneBrickChiseld.blockID, 2, 1);
		world.setBlock(i + 20, j + 2, k + 1, Elysium.blockPalestoneBrickChiseld.blockID, 2, 1);
		world.setBlock(i + 20, j + 2, k + 10, Elysium.blockPalestoneBrickChiseld.blockID, 2, 1);
		world.setBlock(i + 20, j + 3, k + 1, Elysium.blockPalestoneBrickChiseld.blockID, 2, 1);
		world.setBlock(i + 20, j + 3, k + 10, Elysium.blockPalestoneBrickChiseld.blockID, 2, 1);
		world.setBlock(i + 20, j + 4, k + 1, Elysium.blockPalestoneBrickChiseld.blockID, 2, 1);
		world.setBlock(i + 20, j + 4, k + 10, Elysium.blockPalestoneBrickChiseld.blockID, 2, 1);
		world.setBlock(i + 20, j + 5, k + 0, Block.stairsStoneBrick.blockID, 2, 1);
		world.setBlock(i + 20, j + 5, k + 1, Elysium.blockPalestoneBrick.blockID);
		world.setBlock(i + 20, j + 5, k + 2, Elysium.blockPalestoneBrick.blockID);
		world.setBlock(i + 20, j + 5, k + 3, -17);
		world.setBlock(i + 20, j + 5, k + 4, -17);
		world.setBlock(i + 20, j + 5, k + 5, -17);
		world.setBlock(i + 20, j + 5, k + 6, -17);
		world.setBlock(i + 20, j + 5, k + 7, -17);
		world.setBlock(i + 20, j + 5, k + 8, -17);
		world.setBlock(i + 20, j + 5, k + 9, Elysium.blockPalestoneBrick.blockID);
		world.setBlock(i + 20, j + 5, k + 10, Elysium.blockPalestoneBrick.blockID);
		world.setBlock(i + 20, j + 5, k + 11, Block.stairsStoneBrick.blockID, 3, 1);
		world.setBlock(i + 20, j + 6, k + 1, Block.stairsStoneBrick.blockID, 2, 1);
		world.setBlock(i + 20, j + 6, k + 2, Elysium.blockPalestoneBrick.blockID);
		world.setBlock(i + 20, j + 6, k + 3, Elysium.blockPalestoneBrick.blockID);
		world.setBlock(i + 20, j + 6, k + 4, -17);
		world.setBlock(i + 20, j + 6, k + 5, -17);
		world.setBlock(i + 20, j + 6, k + 6, -17);
		world.setBlock(i + 20, j + 6, k + 7, -17);
		world.setBlock(i + 20, j + 6, k + 8, Elysium.blockPalestoneBrick.blockID);
		world.setBlock(i + 20, j + 6, k + 9, Elysium.blockPalestoneBrick.blockID);
		world.setBlock(i + 20, j + 6, k + 10, Block.stairsStoneBrick.blockID, 3, 1);
		world.setBlock(i + 20, j + 7, k + 2, Block.stairsStoneBrick.blockID, 2, 1);
		world.setBlock(i + 20, j + 7, k + 3, Elysium.blockPalestoneBrick.blockID);
		world.setBlock(i + 20, j + 7, k + 4, Elysium.blockPalestoneBrick.blockID);
		world.setBlock(i + 20, j + 7, k + 5, -17);
		world.setBlock(i + 20, j + 7, k + 6, -17);
		world.setBlock(i + 20, j + 7, k + 7, Elysium.blockPalestoneBrick.blockID);
		world.setBlock(i + 20, j + 7, k + 8, Elysium.blockPalestoneBrick.blockID);
		world.setBlock(i + 20, j + 7, k + 9, Block.stairsStoneBrick.blockID, 3, 1);
		world.setBlock(i + 20, j + 8, k + 3, Block.stairsStoneBrick.blockID, 2, 1);
		world.setBlock(i + 20, j + 8, k + 4, Elysium.blockPalestoneBrick.blockID);
		world.setBlock(i + 20, j + 8, k + 5, Elysium.blockPalestoneBrick.blockID);
		world.setBlock(i + 20, j + 8, k + 6, Elysium.blockPalestoneBrick.blockID);
		world.setBlock(i + 20, j + 8, k + 7, Elysium.blockPalestoneBrick.blockID);
		world.setBlock(i + 20, j + 8, k + 8, Block.stairsStoneBrick.blockID, 3, 1);
		world.setBlock(i + 20, j + 9, k + 4, Block.stairsStoneBrick.blockID, 2, 1);
		world.setBlock(i + 20, j + 9, k + 5, Elysium.blockPalestoneBrick.blockID);
		world.setBlock(i + 20, j + 9, k + 6, Elysium.blockPalestoneBrick.blockID);
		world.setBlock(i + 20, j + 9, k + 7, Block.stairsStoneBrick.blockID, 3, 1);
		world.setBlock(i + 20, j + 10, k + 5, Block.stairsStoneBrick.blockID, 2, 1);
		world.setBlock(i + 20, j + 10, k + 6, Block.stairsStoneBrick.blockID, 3, 1);
		world.setBlock(i + 21, j + 0, k + 0, Block.grass.blockID);
		world.setBlock(i + 21, j + 0, k + 1, Block.grass.blockID);
		world.setBlock(i + 21, j + 0, k + 2, Block.grass.blockID);
		world.setBlock(i + 21, j + 0, k + 3, Block.grass.blockID);
		world.setBlock(i + 21, j + 0, k + 4, Block.grass.blockID);
		world.setBlock(i + 21, j + 0, k + 5, Block.grass.blockID);
		world.setBlock(i + 21, j + 0, k + 6, Block.grass.blockID);
		world.setBlock(i + 21, j + 0, k + 7, Block.grass.blockID);
		world.setBlock(i + 21, j + 0, k + 8, Block.grass.blockID);
		world.setBlock(i + 21, j + 0, k + 9, Block.grass.blockID);
		world.setBlock(i + 21, j + 0, k + 10, Block.grass.blockID);
		world.setBlock(i + 21, j + 0, k + 11, Block.grass.blockID);
		world.setBlock(i + 21, j + 5, k + 0, Block.stairsStoneBrick.blockID, 2, 1);
		world.setBlock(i + 21, j + 5, k + 1, Block.stairsStoneBrick.blockID, 7, 1);
		world.setBlock(i + 21, j + 5, k + 10, Block.stairsStoneBrick.blockID, 6, 1);
		world.setBlock(i + 21, j + 5, k + 11, Block.stairsStoneBrick.blockID, 3, 1);
		world.setBlock(i + 21, j + 6, k + 1, Block.stairsStoneBrick.blockID, 2, 1);
		world.setBlock(i + 21, j + 6, k + 2, Block.stairsStoneBrick.blockID, 7, 1);
		world.setBlock(i + 21, j + 6, k + 9, Block.stairsStoneBrick.blockID, 6, 1);
		world.setBlock(i + 21, j + 6, k + 10, Block.stairsStoneBrick.blockID, 3, 1);
		world.setBlock(i + 21, j + 7, k + 2, Block.stairsStoneBrick.blockID, 2, 1);
		world.setBlock(i + 21, j + 7, k + 3, Block.stairsStoneBrick.blockID, 7, 1);
		world.setBlock(i + 21, j + 7, k + 8, Block.stairsStoneBrick.blockID, 6, 1);
		world.setBlock(i + 21, j + 7, k + 9, Block.stairsStoneBrick.blockID, 3, 1);
		world.setBlock(i + 21, j + 8, k + 3, Block.stairsStoneBrick.blockID, 2, 1);
		world.setBlock(i + 21, j + 8, k + 4, Block.stairsStoneBrick.blockID, 7, 1);
		world.setBlock(i + 21, j + 8, k + 7, Block.stairsStoneBrick.blockID, 6, 1);
		world.setBlock(i + 21, j + 8, k + 8, Block.stairsStoneBrick.blockID, 3, 1);
		world.setBlock(i + 21, j + 9, k + 4, Block.stairsStoneBrick.blockID, 2, 1);
		world.setBlock(i + 21, j + 9, k + 5, Block.stairsStoneBrick.blockID, 7, 1);
		world.setBlock(i + 21, j + 9, k + 6, Block.stairsStoneBrick.blockID, 6, 1);
		world.setBlock(i + 21, j + 9, k + 7, Block.stairsStoneBrick.blockID, 3, 1);
		world.setBlock(i + 21, j + 10, k + 5, Block.stairsStoneBrick.blockID, 2, 1);
		world.setBlock(i + 21, j + 10, k + 6, Block.stairsStoneBrick.blockID, 3, 1);
		world.setBlock(i + 3, j + 4, k + 2, Block.torchWood.blockID, 3, 1);
		world.setBlock(i + 3, j + 4, k + 9, Block.torchWood.blockID, 4, 1);
		world.setBlock(i + 14, j + 4, k + 2, Block.torchWood.blockID, 3, 1);
		world.setBlock(i + 14, j + 4, k + 9, Block.torchWood.blockID, 4, 1);

		return true;
	}
}